Workbook

Sheet Sheet1
A1: PANITIA UJIAN AKHIR | G1: PANITIA UJIAN AKHIR
A2: THORIQOH BACA TULIS DAN MENGHAFAL ALQUR'AN | G2: THORIQOH BACA TULIS DAN MENGHAFAL ALQUR'AN
A3: YANBU'A | G3: YANBU'A
A4: 25 | G4: 26
A16: PANITIA UJIAN AKHIR | G16: PANITIA UJIAN AKHIR
A17: THORIQOH BACA TULIS DAN MENGHAFAL ALQUR'AN | G17: THORIQOH BACA TULIS DAN MENGHAFAL ALQUR'AN
A18: YANBU'A | G18: YANBU'A
A19: 27 | G19: 28
A31: PANITIA UJIAN AKHIR | G31: PANITIA UJIAN AKHIR
A32: THORIQOH BACA TULIS DAN MENGHAFAL ALQUR'AN | G32: THORIQOH BACA TULIS DAN MENGHAFAL ALQUR'AN
A33: YANBU'A | G33: YANBU'A
A34: 29 | G34: 30
A46: PANITIA UJIAN AKHIR | G46: PANITIA UJIAN AKHIR
A47: THORIQOH BACA TULIS DAN MENGHAFAL ALQUR'AN | G47: THORIQOH BACA TULIS DAN MENGHAFAL ALQUR'AN
A48: YANBU'A | G48: YANBU'A
A49: 31 | G49: 16

Sheet Data
A1: No | B1: Nama | C1: Asal RTQ | G1: Tambak Jaya, Maret 2018
A4: 1 | B4: Ahmad Ma'ruf | C4: Utsmaniyyah II
A5: 2 | B5: Ahmad Nidlomi | C5: Utsmaniyyah II
A6: 3 | B6: A'ti Lailatin Na'im | C6: Utsmaniyyah II
A7: 4 | B7: Aulia Zahra | C7: Utsmaniyyah II
A8: 5 | B8: Aura Berliana Matin | C8: Utsmaniyyah II
A9: 6 | B9: Evi Nurmala Sari | C9: Utsmaniyyah II
A10: 7 | B10: Halimah Sa'diyah | C10: Utsmaniyyah II
A11: 8 | B11: Halimah Sya'diah | C11: Utsmaniyyah II
A12: 9 | B12: Heru Setiawan | C12: Utsmaniyyah II
A13: 10 | B13: Iis Qomariyah | C13: Utsmaniyyah II
A14: 11 | B14: Keyla Runisya | C14: Utsmaniyyah II
A15: 12 | B15: Kurnia Lestari | C15: Utsmaniyyah II
... A34: 31 | B34: Wulan Suci Ramadhani | C34: Utsmaniyyah II
A35: 32 | C35: Utsmaniyyah II
A36: 33 | C36: Utsmaniyyah II
A37: 34 | C37: Utsmaniyyah II
A38: 35 | C38: Utsmaniyyah II
A39: 36

Sheet S. DEPAN
H2: 6
B3: وماشـهدناالابماعلمنا
B4: SYAHADAH
B6: ROUDLOTU TARBIYATIL QUR’AN
B7: LAJNAH MUROQOBAH LEMBAGA PENDIDIKAN AL-QUR’AN
B8: THORIQOH BACA TULIS DAN MENGHAFAL AL-QUR’AN YANBU’A
B9: KABUPATEN LAMPUNG BARAT
B11: =CONCATENATE("Nomor : ",VLOOKUP(H2,'Data '!$A$2:$L$22,11,0)) -> Nomor : LMY-LB/RTQ-U3/006/09/10/2025
B12: Setelah mengadakan ujian akhir RTQ tingkat dasar pada tanggal 14 Rabi'ul Awwal 1447 H. / 07 September 2025 M. yang diselenggarakan di RTQ UTSMANIYYAH III Jl.Tirtomoyo, No.083, Margorahayu, Desa Tambak Jaya Kec, Way Tenong Kab, Lampung Barat, maka kami menyatakan bahwa anak yang bernama:
B14: =VLOOKUP(H2,'Data '!$A$2:$K$22,3,0) -> Renoval Faiz Al Ghifari
B16: =IF(VLOOKUP(H2,'Data '!$A$2:$J$22,5,0)="L","Bin","Binti") -> Bin | C16: : | D16: =VLOOKUP(H2,'Data '!$A$2:$K$22,6,0) -> Agus Hariyanto
B17: Tempat / Tanggal Lahir | C17: : | D17: =VLOOKUP(H2,'Data '!$A$2:$K$22,4,0) -> Tambak Jaya, 06 September 2013
B18: No Induk Santri | C18: : | D18: =VLOOKUP(H2,'Data '!$A$2:$K$22,9,0) -> 0008
B19: Alamat | C19: : | D19: =VLOOKUP(H2,'Data '!$A$2:$K$22,8,0) -> Margo Mulyo, Tambak Jaya Kec. Way Tenong Kab. Lampung Barat
B21: Dinyatakan Khotam dan Lulus tingkat dasar di lembaga Roudlotu Tarbiyatil Qur’an dan sebagai bukti kepadanya diberikan Syahadah. Semoga Allah memberinya ilmu yang bermanfaat. Aamiin.
D23: Lampung Barat, 21 September 2025
D24: Lajnah Muroqobah Yanbu’a
D29: SYABUL MUBAROK

Sheet S. BELAKANG
B4: DAFTAR NILAI UJIAN AKHIR RTQ
B5: TAHUN PELAJARAN 2025 M/ 1447 H
C7: Nama | D7: : | E7: ='S. DEPAN'!B14 -> Renoval Faiz Al Ghifari
C8: Tempat, Tangggal Lahir | D8: : | E8: ='S. DEPAN'!D17 -> Tambak Jaya, 06 September 2013
C9: Asal RTQ | D9: : | E9: Utsmaniyah III
C10: Nomor Induk Santri | D10: : | E10: ='S. DEPAN'!D18 -> 0008
C11: Nomor Ujian | D11: : | E11: =VLOOKUP('S. DEPAN'!H2,'Data '!$A$2:$K$12,10,0) -> 0008
B14: NO | C14: MATA UJIAN | E14: NILAI
E15: ANGKA | F15: HURUF
B16: 1 | C16: Tartil Fashohah | E16: =VLOOKUP('S. DEPAN'!H2,REKAP1!A8:P25,9,0) -> 65 | F16: =SUBSTITUTE(SUBSTITUTE(SUBSTITUTE(SUBSTITUTE(SUBSTITUTE(SUBSTITUTE(SUBSTITUTE(SUBSTITUTE(SUBSTITUTE(SUBSTITUTE(SUBSTITUTE(TEXT(E16,"#"), 0,"Nol "),1,"Satu "),2,"Dua "),3,"Tiga "),4,"Empat "),5,"Lima "),6,"Enam "),7,"Tujuh "),8,"Delapan "),9,"Sembilan "),",","Koma ") -> Enam Lima
B17: 2 | C17: Ghoroibul Qur'an | E17: =VLOOKUP('S. DEPAN'!H2,REKAP1!A8:P25,10,0) -> 70 | F17: =SUBSTITUTE(SUBSTITUTE(SUBSTITUTE(SUBSTITUTE(SUBSTITUTE(SUBSTITUTE(SUBSTITUTE(SUBSTITUTE(SUBSTITUTE(SUBSTITUTE(SUBSTITUTE(TEXT(E17,"#"), 0,"Nol "),1,"Satu "),2,"Dua "),3,"Tiga "),4,"Empat "),5,"Lima "),6,"Enam "),7,"Tujuh "),8,"Delapan "),9,"Sembilan "),",","Koma ") -> Tujuh Nol
B18: 3 | C18: Ilmu Tajwid | E18: =VLOOKUP('S. DEPAN'!H2,REKAP1!A8:P25,4,0) -> 75 | F18: =SUBSTITUTE(SUBSTITUTE(SUBSTITUTE(SUBSTITUTE(SUBSTITUTE(SUBSTITUTE(SUBSTITUTE(SUBSTITUTE(SUBSTITUTE(SUBSTITUTE(SUBSTITUTE(TEXT(E18,"#"), 0,"Nol "),1,"Satu "),2,"Dua "),3,"Tiga "),4,"Empat "),5,"Lima "),6,"Enam "),7,"Tujuh "),8,"Delapan "),9,"Sembilan "),",","Koma ") -> Tujuh Lima
B19: 4 | C19: Tauhid Dasar | E19: =VLOOKUP('S. DEPAN'!H2,REKAP1!A8:P25,5,0) -> 70 | F19: =SUBSTITUTE(SUBSTITUTE(SUBSTITUTE(SUBSTITUTE(SUBSTITUTE(SUBSTITUTE(SUBSTITUTE(SUBSTITUTE(SUBSTITUTE(SUBSTITUTE(SUBSTITUTE(TEXT(E19,"#"), 0,"Nol "),1,"Satu "),2,"Dua "),3,"Tiga "),4,"Empat "),5,"Lima "),6,"Enam "),7,"Tujuh "),8,"Delapan "),9,"Sembilan "),",","Koma ") -> Tujuh Nol
B20: 5 | C20: Praktik Wudlu | E20: =VLOOKUP('S. DEPAN'!H2,REKAP1!A8:P25,7,0) -> 65 | F20: =SUBSTITUTE(SUBSTITUTE(SUBSTITUTE(SUBSTITUTE(SUBSTITUTE(SUBSTITUTE(SUBSTITUTE(SUBSTITUTE(SUBSTITUTE(SUBSTITUTE(SUBSTITUTE(TEXT(E20,"#"), 0,"Nol "),1,"Satu "),2,"Dua "),3,"Tiga "),4,"Empat "),5,"Lima "),6,"Enam "),7,"Tujuh "),8,"Delapan "),9,"Sembilan "),",","Koma ") -> Enam Lima
B21: 6 | C21: Praktik Sholat | E21: =VLOOKUP('S. DEPAN'!H2,REKAP1!A8:P25,12,0) -> 90 | F21: =SUBSTITUTE(SUBSTITUTE(SUBSTITUTE(SUBSTITUTE(SUBSTITUTE(SUBSTITUTE(SUBSTITUTE(SUBSTITUTE(SUBSTITUTE(SUBSTITUTE(SUBSTITUTE(TEXT(E21,"#"), 0,"Nol "),1,"Satu "),2,"Dua "),3,"Tiga "),4,"Empat "),5,"Lima "),6,"Enam "),7,"Tujuh "),8,"Delapan "),9,"Sembilan "),",","Koma ") -> Sembilan Nol
B22: 7 | C22: Hafalan Surat Pendek | E22: =VLOOKUP('S. DEPAN'!H2,REKAP1!A8:P25,11,0) -> 60 | F22: =SUBSTITUTE(SUBSTITUTE(SUBSTITUTE(SUBSTITUTE(SUBSTITUTE(SUBSTITUTE(SUBSTITUTE(SUBSTITUTE(SUBSTITUTE(SUBSTITUTE(SUBSTITUTE(TEXT(E22,"#"), 0,"Nol "),1,"Satu "),2,"Dua "),3,"Tiga "),4,"Empat "),5,"Lima "),6,"Enam "),7,"Tujuh "),8,"Delapan "),9,"Sembilan "),",","Koma ") -> Enam Nol
B23: 8 | C23: Hafalan Do'a Harian | E23: =VLOOKUP('S. DEPAN'!H2,REKAP1!A8:P25,8,0) -> 65 | F23: =SUBSTITUTE(SUBSTITUTE(SUBSTITUTE(SUBSTITUTE(SUBSTITUTE(SUBSTITUTE(SUBSTITUTE(SUBSTITUTE(SUBSTITUTE(SUBSTITUTE(SUBSTITUTE(TEXT(E23,"#"), 0,"Nol "),1,"Satu "),2,"Dua "),3,"Tiga "),4,"Empat "),5,"Lima "),6,"Enam "),7,"Tujuh "),8,"Delapan "),9,"Sembilan "),",","Koma ") -> Enam Lima
B24: 9 | C24: Kitabah | E24: =VLOOKUP('S. DEPAN'!H2,REKAP1!A8:P25,6,0) -> 65 | F24: =SUBSTITUTE(SUBSTITUTE(SUBSTITUTE(SUBSTITUTE(SUBSTITUTE(SUBSTITUTE(SUBSTITUTE(SUBSTITUTE(SUBSTITUTE(SUBSTITUTE(SUBSTITUTE(TEXT(E24,"#"), 0,"Nol "),1,"Satu "),2,"Dua "),3,"Tiga "),4,"Empat "),5,"Lima "),6,"Enam "),7,"Tujuh "),8,"Delapan "),9,"Sembilan "),",","Koma ") -> Enam Lima
B25: JUMLAH | E25: =VLOOKUP('S. DEPAN'!H2,REKAP1!A8:Z25,14,0) -> 625 | F25: =SUBSTITUTE(SUBSTITUTE(SUBSTITUTE(SUBSTITUTE(SUBSTITUTE(SUBSTITUTE(SUBSTITUTE(SUBSTITUTE(SUBSTITUTE(SUBSTITUTE(SUBSTITUTE(TEXT(E25,"#"), 0,"Nol "),1,"Satu "),2,"Dua "),3,"Tiga "),4,"Empat "),5,"Lima "),6,"Enam "),7,"Tujuh "),8,"Delapan "),9,"Sembilan "),",","Koma ") -> Enam Dua Lima
F28: Tambak Jaya, 07 September 2025
C29: Kepala RTQ Utsmaniyah III | F29: Ketua Tim Penguji
C34: ABU HANIFAN | F34: IKHWANUL KIROM

Sheet Data 
A2: No | B2: RTQ | C2: Nama Peserta | D2: Tempat Tanggal Lahir | E2: Jenis Kelamin | F2: Nama Ayah | G2: Nama Ibu | H2: Alamat | I2: no induk | J2: NO UJIAN
A3: 1 | B3: Utsmaniyyah III | C3: Ahmad Alhabib Ramadhan | D3: Sekincau, 12 Agustus 2012 | E3: L | F3: Indra Saputra | G3: Lilik Sulastri | H3: Margodadi, Tambak Jaya Kec.Way Tenong Kab. Lampung Barat | I3: 0006 | J3: 0006 | K3: LMY-LB/RTQ-U3/001/09/10/2025
A4: =A3+1 -> 2 | B4: Utsmaniyyah III | C4: Aulia Zahra El Fikri | D4: Tambak Jaya, 26 Juli 2007 | E4: P | F4: M.Fikri | G4: Eni Lestari | H4: Margorahayu, Tambak Jaya Kec. Way Tenong Kab. Lampung Barat | I4: 0001 | J4: 0001 | K4: LMY-LB/RTQ-U3/002/09/10/2025
A5: =A4+1 -> 3 | B5: Utsmaniyyah III | C5: Nur Habibi | E5: L | I5: 0003 | J5: 0003 | K5: LMY-LB/RTQ-U3/003/09/10/2025
A6: =A5+1 -> 4 | B6: Utsmaniyyah III | C6: M. Fatan Azzamy Isma'il | D6: Lampung Barat, 11 Juni 2014 | E6: L | F6: Andi Rohman | G6: Hanik Farida | H6: Margodadi, Tambak Jaya Kec.Way Tenong Kab. Lampung Barat | I6: 0009 | J6: 0009 | K6: LMY-LB/RTQ-U3/004/09/10/2025
A7: =A6+1 -> 5 | B7: Utsmaniyyah III | C7: M. Mahi Mutawakkil | D7: Padang Tambak, 22 Desember 2012 | E7: L | F7: Kastahar | G7: Nur Indah | H7: Margodadi, Tambak Jaya Kec.Way Tenong Kab. Lampung Barat | I7: 0007 | J7: 0007 | K7: LMY-LB/RTQ-U3/005/09/10/2025
A8: =A7+1 -> 6 | B8: Utsmaniyyah III | C8: Renoval Faiz Al Ghifari | D8: Tambak Jaya, 06 September 2013 | E8: L | F8: Agus Hariyanto | G8: Supiatun | H8: Margo Mulyo, Tambak Jaya Kec. Way Tenong Kab. Lampung Barat | I8: 0008 | J8: 0008 | K8: LMY-LB/RTQ-U3/006/09/10/2025
A9: =A8+1 -> 7 | B9: Utsmaniyyah III | C9: Sindi Wulandari | D9: Tambak Jaya, 26 Desember 2011 | E9: P | F9: Jaenuri | G9: Siti Alfiah | H9: Margorahayu, Tambak Jaya Kec. Way Tenong Kab. Lampung Barat | I9: 0005 | J9: 0005 | K9: LMY-LB/RTQ-U3/007/09/10/2025
A10: =A9+1 -> 8 | K10: LMY-LB/RTQ-U3/007/09/10/2025
A11: =A10+1 -> 9
A12: =A11+1 -> 10
A13: =A12+1 -> 11
A14: =A13+1 -> 12
A15: =A14+1 -> 13
A16: =A15+1 -> 14
A17: =A16+1 -> 15
A18: =A17+1 -> 16
A19: =A18+1 -> 17
A20: =A19+1 -> 18
A21: =A20+1 -> 19
A22: =A21+1 -> 20
... A36: =A35+1 -> 34
H38: Tambak Jaya, September 2025

Sheet data aplikasi
A1: Nama RTQ | B1: Utsmaniyyah III

Sheet REKAP1
A1: DAFTAR NILAI UJIAN AKHIR
A2: LAJNAH MUROQOBAH YANBU'A LAMPUNG BARAT
A4: 1 | B4: 2 | C4: 3 | D4: 4 | E4: 5 | F4: 6 | G4: 7 | H4: 8 | I4: 9 | J4: 10 | K4: 11 | L4: 12 | M4: 13
A5: No | B5: Nama | C5: Asal RTQ | D5: Nomor Urut Materi | N5: Total Nilai | O5: Rank | P5: Keterangan
D7: Tajwid | E7: Tauhid | F7: Kitabah | G7: Wudhu | H7: Do'a Harian | I7: Tartil Fasohah | J7: Ghorib | K7: Surat Pendek | L7: Fasholatan
A8: 1 | B8: =VLOOKUP(A8,'Data '!A2:J36,3,0) -> Ahmad Alhabib Ramadhan | C8: =VLOOKUP(A8,'Data '!A2:J36,2,0) -> Utsmaniyyah III | D8: =REKAP!D8*10 -> 70 | E8: =REKAP!E8*10 -> 100 | F8: =REKAP!F8*10 -> 75 | G8: =REKAP!G8*10 -> 85 | H8: =REKAP!H8*10 -> 75 | I8: =REKAP!I8*10 -> 75 | J8: =REKAP!J8*10 -> 65 | K8: =REKAP!K8*10 -> 80 | L8: =REKAP!L8*10 -> 80 | N8: =SUM(D8:M8) -> 705 | O8: =RANK(N8,$N$8:$N$28,0) -> 2
A9: 2 | B9: =VLOOKUP(A9,'Data '!A3:J37,3,0) -> Aulia Zahra El Fikri | C9: =VLOOKUP(A9,'Data '!A3:J37,2,0) -> Utsmaniyyah III | D9: =REKAP!D9*10 -> 85 | E9: =REKAP!E9*10 -> 100 | F9: =REKAP!F9*10 -> 80 | G9: =REKAP!G9*10 -> 80 | H9: =REKAP!H9*10 -> 80 | I9: =REKAP!I9*10 -> 75 | J9: =REKAP!J9*10 -> 60 | K9: =REKAP!K9*10 -> 75 | L9: =REKAP!L9*10 -> 80 | N9: =SUM(D9:M9) -> 715 | O9: =RANK(N9,$N$8:$N$28,0) -> 1
A10: 3 | B10: =VLOOKUP(A10,'Data '!A4:J38,3,0) -> Nur Habibi | C10: =VLOOKUP(A10,'Data '!A4:J38,2,0) -> Utsmaniyyah III | D10: =REKAP!D10*10 -> 55 | E10: =REKAP!E10*10 -> 65 | F10: =REKAP!F10*10 -> 90 | G10: =REKAP!G10*10 -> 65 | H10: =REKAP!H10*10 -> 55 | I10: =REKAP!I10*10 -> 62.5 | J10: =REKAP!J10*10 -> 60 | K10: =REKAP!K10*10 -> 55 | L10: =REKAP!L10*10 -> 85 | N10: =SUM(D10:M10) -> 592.5 | O10: =RANK(N10,$N$8:$N$28,0) -> 6
A11: 4 | B11: =VLOOKUP(A11,'Data '!A5:J39,3,0) -> M. Fatan Azzamy Isma'il | C11: =VLOOKUP(A11,'Data '!A5:J39,2,0) -> Utsmaniyyah III | D11: =REKAP!D11*10 -> 60 | E11: =REKAP!E11*10 -> 80 | F11: =REKAP!F11*10 -> 60 | G11: =REKAP!G11*10 -> 80 | H11: =REKAP!H11*10 -> 65 | I11: =REKAP!I11*10 -> 70 | J11: =REKAP!J11*10 -> 60 | K11: =REKAP!K11*10 -> 85 | L11: =REKAP!L11*10 -> 80 | N11: =SUM(D11:M11) -> 640 | O11: =RANK(N11,$N$8:$N$28,0) -> 4
A12: 5 | B12: =VLOOKUP(A12,'Data '!A6:J40,3,0) -> M. Mahi Mutawakkil | C12: =VLOOKUP(A12,'Data '!A6:J40,2,0) -> Utsmaniyyah III | D12: =REKAP!D12*10 -> 70 | E12: =REKAP!E12*10 -> 80 | F12: =REKAP!F12*10 -> 85 | G12: =REKAP!G12*10 -> 90 | H12: =REKAP!H12*10 -> 70 | I12: =REKAP!I12*10 -> 70 | J12: =REKAP!J12*10 -> 80 | K12: =REKAP!K12*10 -> 80 | L12: =REKAP!L12*10 -> 80 | N12: =SUM(D12:M12) -> 705 | O12: =RANK(N12,$N$8:$N$28,0) -> 2
A13: 6 | B13: =VLOOKUP(A13,'Data '!A7:J41,3,0) -> Renoval Faiz Al Ghifari | C13: =VLOOKUP(A13,'Data '!A7:J41,2,0) -> Utsmaniyyah III | D13: =REKAP!D13*10 -> 75 | E13: =REKAP!E13*10 -> 70 | F13: =REKAP!F13*10 -> 65 | G13: =REKAP!G13*10 -> 65 | H13: =REKAP!H13*10 -> 65 | I13: =REKAP!I13*10 -> 65 | J13: =REKAP!J13*10 -> 70 | K13: =REKAP!K13*10 -> 60 | L13: =REKAP!L13*10 -> 90 | N13: =SUM(D13:M13) -> 625 | O13: =RANK(N13,$N$8:$N$28,0) -> 5
A14: 7 | B14: =VLOOKUP(A14,'Data '!A8:J42,3,0) -> Sindi Wulandari | C14: =VLOOKUP(A14,'Data '!A8:J42,2,0) -> Utsmaniyyah III | D14: =REKAP!D14*10 -> 60 | E14: =REKAP!E14*10 -> 80 | F14: =REKAP!F14*10 -> 60 | G14: =REKAP!G14*10 -> 90 | H14: =REKAP!H14*10 -> 50 | I14: =REKAP!I14*10 -> 60 | J14: =REKAP!J14*10 -> 50 | K14: =REKAP!K14*10 -> 60 | L14: =REKAP!L14*10 -> 80 | N14: =SUM(D14:M14) -> 590 | O14: =RANK(N14,$N$8:$N$28,0) -> 7
A15: 8 | B15: =VLOOKUP(A15,'Data '!A8:J43,3,0) -> 0 | C15: =VLOOKUP(A15,'Data '!A8:J43,2,0) -> 0 | E15: =tauhid!N15 -> 0 | F15: =kitabah!N15 -> 0 | G15: =Wudlu!N15 -> 0 | H15: ='doa harian'!N15 -> 0 | I15: ='Tartil dan Fashohah'!L15 -> 0 | J15: ='Ghoroib '!N15 -> 0 | K15: ='Surat Pendek'!N15 -> 0 | L15: =Fasolatan!N15 -> 0 | N15: =SUM(D15:M15) -> 0 | O15: =RANK(N15,$N$8:$N$28,0) -> 8
A16: 9 | B16: =VLOOKUP(A16,'Data '!A9:J44,3,0) -> 0 | C16: =VLOOKUP(A16,'Data '!A9:J44,2,0) -> 0 | D16: =tajwid!N16 -> 0 | E16: =tauhid!N16 -> 0 | F16: =kitabah!N16 -> 0 | G16: =Wudlu!N16 -> 0 | H16: ='doa harian'!N16 -> 0 | I16: ='Tartil dan Fashohah'!L16 -> 0 | J16: ='Ghoroib '!N16 -> 0 | K16: ='Surat Pendek'!N16 -> 0 | L16: =Fasolatan!N16 -> 0 | N16: =SUM(D16:M16) -> 0
A17: 10 | B17: =VLOOKUP(A17,'Data '!A10:J45,3,0) -> 0 | C17: =VLOOKUP(A17,'Data '!A10:J45,2,0) -> 0 | D17: =tajwid!N17 -> 0 | E17: =tauhid!N17 -> 0 | F17: =kitabah!N17 -> 0 | G17: =Wudlu!N17 -> 0 | H17: ='doa harian'!N17 -> 0 | I17: ='Tartil dan Fashohah'!L17 -> 0 | J17: ='Ghoroib '!N17 -> 0 | K17: ='Surat Pendek'!N17 -> 0 | L17: =Fasolatan!N17 -> 0 | N17: =SUM(D17:M17) -> 0
A18: 11 | B18: =VLOOKUP(A18,'Data '!A11:J46,3,0) -> 0 | C18: =VLOOKUP(A18,'Data '!A11:J46,2,0) -> 0 | D18: =tajwid!N18 -> 0 | E18: =tauhid!N18 -> 0 | F18: =kitabah!N18 -> 0 | G18: =Wudlu!N18 -> 0 | H18: ='doa harian'!N18 -> 0 | I18: ='Tartil dan Fashohah'!L18 -> 0 | J18: ='Ghoroib '!N18 -> 0 | K18: ='Surat Pendek'!N18 -> 0 | L18: =Fasolatan!N18 -> 0 | N18: =SUM(D18:M18) -> 0
A19: 12 | B19: =VLOOKUP(A19,'Data '!A12:J47,3,0) -> 0 | C19: =VLOOKUP(A19,'Data '!A12:J47,2,0) -> 0 | D19: =tajwid!N19 -> 0 | E19: =tauhid!N19 -> 0 | F19: =kitabah!N19 -> 0 | G19: =Wudlu!N19 -> 0 | H19: ='doa harian'!N19 -> 0 | I19: ='Tartil dan Fashohah'!L19 -> 0 | J19: ='Ghoroib '!N19 -> 0 | K19: ='Surat Pendek'!N19 -> 0 | L19: =Fasolatan!N19 -> 0 | N19: =SUM(D19:M19) -> 0
A20: 13 | B20: =VLOOKUP(A20,'Data '!A13:J48,3,0) -> 0 | C20: =VLOOKUP(A20,'Data '!A13:J48,2,0) -> 0 | D20: =tajwid!N20 -> 0 | E20: =tauhid!N20 -> 0 | F20: =kitabah!N20 -> 0 | G20: =Wudlu!N20 -> 0 | H20: ='doa harian'!N20 -> 0 | I20: ='Tartil dan Fashohah'!L20 -> 0 | J20: ='Ghoroib '!N20 -> 0 | K20: ='Surat Pendek'!N20 -> 0 | L20: =Fasolatan!N20 -> 0 | N20: =SUM(D20:M20) -> 0
A21: 14 | B21: =VLOOKUP(A21,'Data '!A14:J49,3,0) -> 0 | C21: =VLOOKUP(A21,'Data '!A14:J49,2,0) -> 0 | D21: =tajwid!N21 -> 0 | E21: =tauhid!N21 -> 0 | F21: =kitabah!N21 -> 0 | G21: =Wudlu!N21 -> 0 | H21: ='doa harian'!N21 -> 0 | I21: ='Tartil dan Fashohah'!L21 -> 0 | J21: ='Ghoroib '!N21 -> 0 | K21: ='Surat Pendek'!N21 -> 0 | L21: =Fasolatan!N21 -> 0 | N21: =SUM(D21:M21) -> 0
A22: 15 | B22: =VLOOKUP(A22,'Data '!A15:J50,3,0) -> 0 | C22: =VLOOKUP(A22,'Data '!A15:J50,2,0) -> 0 | D22: =tajwid!N22 -> 0 | E22: =tauhid!N22 -> 0 | F22: =kitabah!N22 -> 0 | G22: =Wudlu!N22 -> 0 | H22: ='doa harian'!N22 -> 0 | I22: ='Tartil dan Fashohah'!L22 -> 0 | J22: ='Ghoroib '!N22 -> 0 | K22: ='Surat Pendek'!N22 -> 0 | L22: =Fasolatan!N22 -> 0 | N22: =SUM(D22:M22) -> 0
A23: 16 | B23: =VLOOKUP(A23,'Data '!A16:J51,3,0) -> 0 | C23: =VLOOKUP(A23,'Data '!A16:J51,2,0) -> 0 | D23: =tajwid!N23 -> 0 | E23: =tauhid!N23 -> 0 | F23: =kitabah!N23 -> 0 | G23: =Wudlu!N23 -> 0 | H23: ='doa harian'!N23 -> 0 | I23: ='Tartil dan Fashohah'!L23 -> 0 | J23: ='Ghoroib '!N23 -> 0 | K23: ='Surat Pendek'!N23 -> 0 | L23: =Fasolatan!N23 -> 0 | N23: =SUM(D23:M23) -> 0
A24: 17 | B24: =VLOOKUP(A24,'Data '!A17:J52,3,0) -> 0 | C24: =VLOOKUP(A24,'Data '!A17:J52,2,0) -> 0 | D24: =tajwid!N24 -> 0 | E24: =tauhid!N24 -> 0 | F24: =kitabah!N24 -> 0 | G24: =Wudlu!N24 -> 0 | H24: ='doa harian'!N24 -> 0 | I24: ='Tartil dan Fashohah'!L24 -> 0 | J24: ='Ghoroib '!N24 -> 0 | K24: ='Surat Pendek'!N24 -> 0 | L24: =Fasolatan!N24 -> 0 | N24: =SUM(D24:M24) -> 0
A25: 18 | B25: =VLOOKUP(A25,'Data '!A18:J53,3,0) -> 0 | C25: =VLOOKUP(A25,'Data '!A18:J53,2,0) -> 0 | D25: =tajwid!N25 -> 0 | E25: =tauhid!N25 -> 0 | F25: =kitabah!N25 -> 0 | G25: =Wudlu!N25 -> 0 | H25: ='doa harian'!N25 -> 0 | I25: ='Tartil dan Fashohah'!L25 -> 0 | J25: ='Ghoroib '!N25 -> 0 | K25: ='Surat Pendek'!N25 -> 0 | L25: =Fasolatan!N25 -> 0 | N25: =SUM(D25:M25) -> 0
A26: 19 | B26: =VLOOKUP(A26,'Data '!A19:J54,3,0) -> 0 | C26: =VLOOKUP(A26,'Data '!A19:J54,2,0) -> 0 | D26: =tajwid!N26 -> 0 | E26: =tauhid!N26 -> 0 | F26: =kitabah!N26 -> 0 | G26: =Wudlu!N26 -> 0 | H26: ='doa harian'!N26 -> 0 | I26: ='Tartil dan Fashohah'!L26 -> 0 | J26: ='Ghoroib '!N26 -> 0 | K26: ='Surat Pendek'!N26 -> 0 | L26: =Fasolatan!N26 -> 0 | N26: =SUM(D26:M26) -> 0
A27: 20 | B27: =VLOOKUP(A27,'Data '!A20:J55,3,0) -> 0 | C27: =VLOOKUP(A27,'Data '!A20:J55,2,0) -> 0 | D27: =tajwid!N27 -> 0 | E27: =tauhid!N27 -> 0 | F27: =kitabah!N27 -> 0 | G27: =Wudlu!N27 -> 0 | H27: ='doa harian'!N27 -> 0 | I27: ='Tartil dan Fashohah'!L27 -> 0 | J27: ='Ghoroib '!N27 -> 0 | K27: ='Surat Pendek'!N27 -> 0 | L27: =Fasolatan!N27 -> 0 | N27: =SUM(D27:M27) -> 0
A28: 21 | B28: =VLOOKUP(A28,'Data '!A21:J56,3,0) -> 0 | C28: =VLOOKUP(A28,'Data '!A21:J56,2,0) -> 0 | D28: =tajwid!N28 -> 0 | E28: =tauhid!N28 -> 0 | F28: =kitabah!N28 -> 0 | G28: =Wudlu!N28 -> 0 | H28: ='doa harian'!N28 -> 0 | I28: ='Tartil dan Fashohah'!L28 -> 0 | J28: ='Ghoroib '!N28 -> 0 | K28: ='Surat Pendek'!N28 -> 0 | L28: =Fasolatan!N28 -> 0 | N28: =SUM(D28:M28) -> 0
B30: KET : | K30: ='Data '!H38 -> Tambak Jaya, September 2025
C31: LULUS | K31: Ketua Panitia
C32: TIDAK LULUS
K35: A Muslih Abdurrahman
A37: DAFTAR NILAI UJIAN AKHIR
A38: LAJNAH MUROQOBAH YANBU'A LAMPUNG BARAT
A41: No | B41: Nama | C41: Asal RTQ | D41: Nomor Urut Materi | N41: Total Nilai | P41: Keterangan
D43: Tajwid | E43: Tauhid | F43: Kitabah | G43: Wudhu | H43: Do'a Harian | I43: Tartil Fasohah | J43: Ghorib | K43: Surat Pendek | L43: Fasholatan
A44: 1 | B44: =B8 -> Ahmad Alhabib Ramadhan | C44: Utsmaniyyah III | D44: =IF(D8>=60,"LULUS","TIDAK LULUS") -> LULUS | E44: =IF(E8>=60,"LULUS","TIDAK LULUS") -> LULUS | F44: =IF(F8>=60,"LULUS","TIDAK LULUS") -> LULUS | G44: =IF(G8>=60,"LULUS","TIDAK LULUS") -> LULUS | H44: =IF(H8>=60,"LULUS","TIDAK LULUS") -> LULUS | I44: =IF(I8>=60,"LULUS","TIDAK LULUS") -> LULUS | J44: =IF(J8>=60,"LULUS","TIDAK LULUS") -> LULUS | K44: =IF(K8>=60,"LULUS","TIDAK LULUS") -> LULUS | L44: =IF(L8>=60,"LULUS","TIDAK LULUS") -> LULUS | N44: =SUM(D44:M44) -> 0
A45: 2 | B45: =B9 -> Aulia Zahra El Fikri | C45: Utsmaniyyah III | D45: =IF(D9>=60,"LULUS","TIDAK LULUS") -> LULUS | E45: =IF(E9>=60,"LULUS","TIDAK LULUS") -> LULUS | F45: =IF(F9>=60,"LULUS","TIDAK LULUS") -> LULUS | G45: =IF(G9>=60,"LULUS","TIDAK LULUS") -> LULUS | H45: =IF(H9>=60,"LULUS","TIDAK LULUS") -> LULUS | I45: =IF(I9>=60,"LULUS","TIDAK LULUS") -> LULUS | J45: =IF(J9>=60,"LULUS","TIDAK LULUS") -> LULUS | K45: =IF(K9>=60,"LULUS","TIDAK LULUS") -> LULUS | L45: =IF(L9>=60,"LULUS","TIDAK LULUS") -> LULUS | N45: =SUM(D45:M45) -> 0
A46: 3 | B46: =B10 -> Nur Habibi | C46: Utsmaniyyah III | D46: =IF(D10>=60,"LULUS","TIDAK LULUS") -> TIDAK LULUS | E46: =IF(E10>=60,"LULUS","TIDAK LULUS") -> LULUS | F46: =IF(F10>=60,"LULUS","TIDAK LULUS") -> LULUS | G46: =IF(G10>=60,"LULUS","TIDAK LULUS") -> LULUS | H46: =IF(H10>=60,"LULUS","TIDAK LULUS") -> TIDAK LULUS | I46: =IF(I10>=60,"LULUS","TIDAK LULUS") -> LULUS | J46: =IF(J10>=60,"LULUS","TIDAK LULUS") -> LULUS | K46: =IF(K10>=60,"LULUS","TIDAK LULUS") -> TIDAK LULUS | L46: =IF(L10>=60,"LULUS","TIDAK LULUS") -> LULUS | N46: =SUM(D46:M46) -> 0
A47: 4 | B47: =B11 -> M. Fatan Azzamy Isma'il | C47: Utsmaniyyah III | D47: =IF(D11>=60,"LULUS","TIDAK LULUS") -> LULUS | E47: =IF(E11>=60,"LULUS","TIDAK LULUS") -> LULUS | F47: =IF(F11>=60,"LULUS","TIDAK LULUS") -> LULUS | G47: =IF(G11>=60,"LULUS","TIDAK LULUS") -> LULUS | H47: =IF(H11>=60,"LULUS","TIDAK LULUS") -> LULUS | I47: =IF(I11>=60,"LULUS","TIDAK LULUS") -> LULUS | J47: =IF(J11>=60,"LULUS","TIDAK LULUS") -> LULUS | K47: =IF(K11>=60,"LULUS","TIDAK LULUS") -> LULUS | L47: =IF(L11>=60,"LULUS","TIDAK LULUS") -> LULUS | N47: =SUM(D47:M47) -> 0
A48: 5 | B48: =B12 -> M. Mahi Mutawakkil | C48: Utsmaniyyah III | D48: =IF(D12>=60,"LULUS","TIDAK LULUS") -> LULUS | E48: =IF(E12>=60,"LULUS","TIDAK LULUS") -> LULUS | F48: =IF(F12>=60,"LULUS","TIDAK LULUS") -> LULUS | G48: =IF(G12>=60,"LULUS","TIDAK LULUS") -> LULUS | H48: =IF(H12>=60,"LULUS","TIDAK LULUS") -> LULUS | I48: =IF(I12>=60,"LULUS","TIDAK LULUS") -> LULUS | J48: =IF(J12>=60,"LULUS","TIDAK LULUS") -> LULUS | K48: =IF(K12>=60,"LULUS","TIDAK LULUS") -> LULUS | L48: =IF(L12>=60,"LULUS","TIDAK LULUS") -> LULUS | N48: =SUM(D48:M48) -> 0
A49: 6 | B49: =B13 -> Renoval Faiz Al Ghifari | C49: Utsmaniyyah III | D49: =IF(D13>=60,"LULUS","TIDAK LULUS") -> LULUS | E49: =IF(E13>=60,"LULUS","TIDAK LULUS") -> LULUS | F49: =IF(F13>=60,"LULUS","TIDAK LULUS") -> LULUS | G49: =IF(G13>=60,"LULUS","TIDAK LULUS") -> LULUS | H49: =IF(H13>=60,"LULUS","TIDAK LULUS") -> LULUS | I49: =IF(I13>=60,"LULUS","TIDAK LULUS") -> LULUS | J49: =IF(J13>=60,"LULUS","TIDAK LULUS") -> LULUS | K49: =IF(K13>=60,"LULUS","TIDAK LULUS") -> LULUS | L49: =IF(L13>=60,"LULUS","TIDAK LULUS") -> LULUS | N49: =SUM(D49:M49) -> 0
...

Sheet REKAP
A1: DAFTAR NILAI UJIAN AKHIR
A2: LAJNAH MUROQOBAH YANBU'A LAMPUNG BARAT
A4: 1 | B4: 2 | C4: 3 | D4: 4 | E4: 5 | F4: 6 | G4: 7 | H4: 8 | I4: 9 | J4: 10 | K4: 11 | L4: 12 | M4: 13
A5: No | B5: Nama | C5: Asal RTQ | D5: Nomor Urut Materi | N5: Total Nilai | O5: Rank | P5: Keterangan
D7: Tajwid | E7: Tauhid | F7: Kitabah | G7: Wudhu | H7: Do'a Harian | I7: Tartil Fasohah | J7: Ghorib | K7: Surat Pendek | L7: Fasholatan
A8: 1 | B8: =VLOOKUP(A8,'Data '!A2:J36,3,0) -> Ahmad Alhabib Ramadhan | C8: =VLOOKUP(A8,'Data '!A2:J36,2,0) -> Utsmaniyyah III | D8: 7 | E8: 10 | F8: 7.5 | G8: 8.5 | H8: 7.5 | I8: 7.5 | J8: 6.5 | K8: 8 | L8: 8 | N8: =SUM(D8:M8) -> 70.5 | O8: =RANK(N8,$N$8:$N$28,0) -> 2
A9: 2 | B9: =VLOOKUP(A9,'Data '!A3:J37,3,0) -> Aulia Zahra El Fikri | C9: =VLOOKUP(A9,'Data '!A3:J37,2,0) -> Utsmaniyyah III | D9: 8.5 | E9: 10 | F9: 8 | G9: 8 | H9: 8 | I9: 7.5 | J9: 6 | K9: 7.5 | L9: 8 | N9: =SUM(D9:M9) -> 71.5 | O9: =RANK(N9,$N$8:$N$28,0) -> 1
A10: 3 | B10: =VLOOKUP(A10,'Data '!A4:J38,3,0) -> Nur Habibi | C10: =VLOOKUP(A10,'Data '!A4:J38,2,0) -> Utsmaniyyah III | D10: 5.5 | E10: 6.5 | F10: 9 | G10: 6.5 | H10: 5.5 | I10: 6.25 | J10: 6 | K10: 5.5 | L10: 8.5 | N10: =SUM(D10:M10) -> 59.25 | O10: =RANK(N10,$N$8:$N$28,0) -> 6
A11: 4 | B11: =VLOOKUP(A11,'Data '!A5:J39,3,0) -> M. Fatan Azzamy Isma'il | C11: =VLOOKUP(A11,'Data '!A5:J39,2,0) -> Utsmaniyyah III | D11: 6 | E11: 8 | F11: 6 | G11: 8 | H11: 6.5 | I11: 7 | J11: 6 | K11: 8.5 | L11: 8 | N11: =SUM(D11:M11) -> 64 | O11: =RANK(N11,$N$8:$N$28,0) -> 4
A12: 5 | B12: =VLOOKUP(A12,'Data '!A6:J40,3,0) -> M. Mahi Mutawakkil | C12: =VLOOKUP(A12,'Data '!A6:J40,2,0) -> Utsmaniyyah III | D12: 7 | E12: 8 | F12: 8.5 | G12: 9 | H12: 7 | I12: 7 | J12: 8 | K12: 8 | L12: 8 | N12: =SUM(D12:M12) -> 70.5 | O12: =RANK(N12,$N$8:$N$28,0) -> 2
A13: 6 | B13: =VLOOKUP(A13,'Data '!A7:J41,3,0) -> Renoval Faiz Al Ghifari | C13: =VLOOKUP(A13,'Data '!A7:J41,2,0) -> Utsmaniyyah III | D13: 7.5 | E13: 7 | F13: 6.5 | G13: 6.5 | H13: 6.5 | I13: 6.5 | J13: 7 | K13: 6 | L13: 9 | N13: =SUM(D13:M13) -> 62.5 | O13: =RANK(N13,$N$8:$N$28,0) -> 5
A14: 7 | B14: =VLOOKUP(A14,'Data '!A8:J42,3,0) -> Sindi Wulandari | C14: =VLOOKUP(A14,'Data '!A8:J42,2,0) -> Utsmaniyyah III | D14: 6 | E14: 8 | F14: 6 | G14: 9 | H14: 5 | I14: 6 | J14: 5 | K14: 6 | L14: 8 | N14: =SUM(D14:M14) -> 59 | O14: =RANK(N14,$N$8:$N$28,0) -> 7
A15: 8 | B15: =VLOOKUP(A15,'Data '!A8:J43,3,0) -> 0 | C15: =VLOOKUP(A15,'Data '!A8:J43,2,0) -> 0 | E15: =tauhid!N15 -> 0 | F15: =kitabah!N15 -> 0 | G15: =Wudlu!N15 -> 0 | H15: ='doa harian'!N15 -> 0 | I15: ='Tartil dan Fashohah'!L15 -> 0 | J15: ='Ghoroib '!N15 -> 0 | K15: ='Surat Pendek'!N15 -> 0 | L15: =Fasolatan!N15 -> 0 | N15: =SUM(D15:M15) -> 0 | O15: =RANK(N15,$N$8:$N$28,0) -> 8
A16: 9 | B16: =VLOOKUP(A16,'Data '!A9:J44,3,0) -> 0 | C16: =VLOOKUP(A16,'Data '!A9:J44,2,0) -> 0 | D16: =tajwid!N16 -> 0 | E16: =tauhid!N16 -> 0 | F16: =kitabah!N16 -> 0 | G16: =Wudlu!N16 -> 0 | H16: ='doa harian'!N16 -> 0 | I16: ='Tartil dan Fashohah'!L16 -> 0 | J16: ='Ghoroib '!N16 -> 0 | K16: ='Surat Pendek'!N16 -> 0 | L16: =Fasolatan!N16 -> 0 | N16: =SUM(D16:M16) -> 0
A17: 10 | B17: =VLOOKUP(A17,'Data '!A10:J45,3,0) -> 0 | C17: =VLOOKUP(A17,'Data '!A10:J45,2,0) -> 0 | D17: =tajwid!N17 -> 0 | E17: =tauhid!N17 -> 0 | F17: =kitabah!N17 -> 0 | G17: =Wudlu!N17 -> 0 | H17: ='doa harian'!N17 -> 0 | I17: ='Tartil dan Fashohah'!L17 -> 0 | J17: ='Ghoroib '!N17 -> 0 | K17: ='Surat Pendek'!N17 -> 0 | L17: =Fasolatan!N17 -> 0 | N17: =SUM(D17:M17) -> 0
A18: 11 | B18: =VLOOKUP(A18,'Data '!A11:J46,3,0) -> 0 | C18: =VLOOKUP(A18,'Data '!A11:J46,2,0) -> 0 | D18: =tajwid!N18 -> 0 | E18: =tauhid!N18 -> 0 | F18: =kitabah!N18 -> 0 | G18: =Wudlu!N18 -> 0 | H18: ='doa harian'!N18 -> 0 | I18: ='Tartil dan Fashohah'!L18 -> 0 | J18: ='Ghoroib '!N18 -> 0 | K18: ='Surat Pendek'!N18 -> 0 | L18: =Fasolatan!N18 -> 0 | N18: =SUM(D18:M18) -> 0
A19: 12 | B19: =VLOOKUP(A19,'Data '!A12:J47,3,0) -> 0 | C19: =VLOOKUP(A19,'Data '!A12:J47,2,0) -> 0 | D19: =tajwid!N19 -> 0 | E19: =tauhid!N19 -> 0 | F19: =kitabah!N19 -> 0 | G19: =Wudlu!N19 -> 0 | H19: ='doa harian'!N19 -> 0 | I19: ='Tartil dan Fashohah'!L19 -> 0 | J19: ='Ghoroib '!N19 -> 0 | K19: ='Surat Pendek'!N19 -> 0 | L19: =Fasolatan!N19 -> 0 | N19: =SUM(D19:M19) -> 0
A20: 13 | B20: =VLOOKUP(A20,'Data '!A13:J48,3,0) -> 0 | C20: =VLOOKUP(A20,'Data '!A13:J48,2,0) -> 0 | D20: =tajwid!N20 -> 0 | E20: =tauhid!N20 -> 0 | F20: =kitabah!N20 -> 0 | G20: =Wudlu!N20 -> 0 | H20: ='doa harian'!N20 -> 0 | I20: ='Tartil dan Fashohah'!L20 -> 0 | J20: ='Ghoroib '!N20 -> 0 | K20: ='Surat Pendek'!N20 -> 0 | L20: =Fasolatan!N20 -> 0 | N20: =SUM(D20:M20) -> 0
A21: 14 | B21: =VLOOKUP(A21,'Data '!A14:J49,3,0) -> 0 | C21: =VLOOKUP(A21,'Data '!A14:J49,2,0) -> 0 | D21: =tajwid!N21 -> 0 | E21: =tauhid!N21 -> 0 | F21: =kitabah!N21 -> 0 | G21: =Wudlu!N21 -> 0 | H21: ='doa harian'!N21 -> 0 | I21: ='Tartil dan Fashohah'!L21 -> 0 | J21: ='Ghoroib '!N21 -> 0 | K21: ='Surat Pendek'!N21 -> 0 | L21: =Fasolatan!N21 -> 0 | N21: =SUM(D21:M21) -> 0
A22: 15 | B22: =VLOOKUP(A22,'Data '!A15:J50,3,0) -> 0 | C22: =VLOOKUP(A22,'Data '!A15:J50,2,0) -> 0 | D22: =tajwid!N22 -> 0 | E22: =tauhid!N22 -> 0 | F22: =kitabah!N22 -> 0 | G22: =Wudlu!N22 -> 0 | H22: ='doa harian'!N22 -> 0 | I22: ='Tartil dan Fashohah'!L22 -> 0 | J22: ='Ghoroib '!N22 -> 0 | K22: ='Surat Pendek'!N22 -> 0 | L22: =Fasolatan!N22 -> 0 | N22: =SUM(D22:M22) -> 0
A23: 16 | B23: =VLOOKUP(A23,'Data '!A16:J51,3,0) -> 0 | C23: =VLOOKUP(A23,'Data '!A16:J51,2,0) -> 0 | D23: =tajwid!N23 -> 0 | E23: =tauhid!N23 -> 0 | F23: =kitabah!N23 -> 0 | G23: =Wudlu!N23 -> 0 | H23: ='doa harian'!N23 -> 0 | I23: ='Tartil dan Fashohah'!L23 -> 0 | J23: ='Ghoroib '!N23 -> 0 | K23: ='Surat Pendek'!N23 -> 0 | L23: =Fasolatan!N23 -> 0 | N23: =SUM(D23:M23) -> 0
A24: 17 | B24: =VLOOKUP(A24,'Data '!A17:J52,3,0) -> 0 | C24: =VLOOKUP(A24,'Data '!A17:J52,2,0) -> 0 | D24: =tajwid!N24 -> 0 | E24: =tauhid!N24 -> 0 | F24: =kitabah!N24 -> 0 | G24: =Wudlu!N24 -> 0 | H24: ='doa harian'!N24 -> 0 | I24: ='Tartil dan Fashohah'!L24 -> 0 | J24: ='Ghoroib '!N24 -> 0 | K24: ='Surat Pendek'!N24 -> 0 | L24: =Fasolatan!N24 -> 0 | N24: =SUM(D24:M24) -> 0
A25: 18 | B25: =VLOOKUP(A25,'Data '!A18:J53,3,0) -> 0 | C25: =VLOOKUP(A25,'Data '!A18:J53,2,0) -> 0 | D25: =tajwid!N25 -> 0 | E25: =tauhid!N25 -> 0 | F25: =kitabah!N25 -> 0 | G25: =Wudlu!N25 -> 0 | H25: ='doa harian'!N25 -> 0 | I25: ='Tartil dan Fashohah'!L25 -> 0 | J25: ='Ghoroib '!N25 -> 0 | K25: ='Surat Pendek'!N25 -> 0 | L25: =Fasolatan!N25 -> 0 | N25: =SUM(D25:M25) -> 0
A26: 19 | B26: =VLOOKUP(A26,'Data '!A19:J54,3,0) -> 0 | C26: =VLOOKUP(A26,'Data '!A19:J54,2,0) -> 0 | D26: =tajwid!N26 -> 0 | E26: =tauhid!N26 -> 0 | F26: =kitabah!N26 -> 0 | G26: =Wudlu!N26 -> 0 | H26: ='doa harian'!N26 -> 0 | I26: ='Tartil dan Fashohah'!L26 -> 0 | J26: ='Ghoroib '!N26 -> 0 | K26: ='Surat Pendek'!N26 -> 0 | L26: =Fasolatan!N26 -> 0 | N26: =SUM(D26:M26) -> 0
A27: 20 | B27: =VLOOKUP(A27,'Data '!A20:J55,3,0) -> 0 | C27: =VLOOKUP(A27,'Data '!A20:J55,2,0) -> 0 | D27: =tajwid!N27 -> 0 | E27: =tauhid!N27 -> 0 | F27: =kitabah!N27 -> 0 | G27: =Wudlu!N27 -> 0 | H27: ='doa harian'!N27 -> 0 | I27: ='Tartil dan Fashohah'!L27 -> 0 | J27: ='Ghoroib '!N27 -> 0 | K27: ='Surat Pendek'!N27 -> 0 | L27: =Fasolatan!N27 -> 0 | N27: =SUM(D27:M27) -> 0
A28: 21 | B28: =VLOOKUP(A28,'Data '!A21:J56,3,0) -> 0 | C28: =VLOOKUP(A28,'Data '!A21:J56,2,0) -> 0 | D28: =tajwid!N28 -> 0 | E28: =tauhid!N28 -> 0 | F28: =kitabah!N28 -> 0 | G28: =Wudlu!N28 -> 0 | H28: ='doa harian'!N28 -> 0 | I28: ='Tartil dan Fashohah'!L28 -> 0 | J28: ='Ghoroib '!N28 -> 0 | K28: ='Surat Pendek'!N28 -> 0 | L28: =Fasolatan!N28 -> 0 | N28: =SUM(D28:M28) -> 0
B30: KET : | K30: ='Data '!H38 -> Tambak Jaya, September 2025
C31: LULUS | K31: Ketua Panitia
C32: TIDAK LULUS
K35: A Muslih Abdurrahman
A37: DAFTAR NILAI UJIAN AKHIR
A38: LAJNAH MUROQOBAH YANBU'A LAMPUNG BARAT
A41: No | B41: Nama | C41: Asal RTQ | D41: Nomor Urut Materi | N41: Total Nilai | P41: Keterangan
D43: Tajwid | E43: Tauhid | F43: Kitabah | G43: Wudhu | H43: Do'a Harian | I43: Tartil Fasohah | J43: Ghorib | K43: Surat Pendek | L43: Fasholatan
A44: 1 | B44: =B8 -> Ahmad Alhabib Ramadhan | C44: Utsmaniyyah III | D44: =IF(D8>=60,"LULUS","TIDAK LULUS") -> TIDAK LULUS | E44: =IF(E8>=60,"LULUS","TIDAK LULUS") -> TIDAK LULUS | F44: =IF(F8>=60,"LULUS","TIDAK LULUS") -> TIDAK LULUS | G44: =IF(G8>=60,"LULUS","TIDAK LULUS") -> TIDAK LULUS | H44: =IF(H8>=60,"LULUS","TIDAK LULUS") -> TIDAK LULUS | I44: =IF(I8>=60,"LULUS","TIDAK LULUS") -> TIDAK LULUS | J44: =IF(J8>=60,"LULUS","TIDAK LULUS") -> TIDAK LULUS | K44: =IF(K8>=60,"LULUS","TIDAK LULUS") -> TIDAK LULUS | L44: =IF(L8>=60,"LULUS","TIDAK LULUS") -> TIDAK LULUS | N44: =SUM(D44:M44) -> 0
A45: 2 | B45: =B9 -> Aulia Zahra El Fikri | C45: Utsmaniyyah III | D45: =IF(D9>=60,"LULUS","TIDAK LULUS") -> TIDAK LULUS | E45: =IF(E9>=60,"LULUS","TIDAK LULUS") -> TIDAK LULUS | F45: =IF(F9>=60,"LULUS","TIDAK LULUS") -> TIDAK LULUS | G45: =IF(G9>=60,"LULUS","TIDAK LULUS") -> TIDAK LULUS | H45: =IF(H9>=60,"LULUS","TIDAK LULUS") -> TIDAK LULUS | I45: =IF(I9>=60,"LULUS","TIDAK LULUS") -> TIDAK LULUS | J45: =IF(J9>=60,"LULUS","TIDAK LULUS") -> TIDAK LULUS | K45: =IF(K9>=60,"LULUS","TIDAK LULUS") -> TIDAK LULUS | L45: =IF(L9>=60,"LULUS","TIDAK LULUS") -> TIDAK LULUS | N45: =SUM(D45:M45) -> 0
A46: 3 | B46: =B10 -> Nur Habibi | C46: Utsmaniyyah III | D46: =IF(D10>=60,"LULUS","TIDAK LULUS") -> TIDAK LULUS | E46: =IF(E10>=60,"LULUS","TIDAK LULUS") -> TIDAK LULUS | F46: =IF(F10>=60,"LULUS","TIDAK LULUS") -> TIDAK LULUS | G46: =IF(G10>=60,"LULUS","TIDAK LULUS") -> TIDAK LULUS | H46: =IF(H10>=60,"LULUS","TIDAK LULUS") -> TIDAK LULUS | I46: =IF(I10>=60,"LULUS","TIDAK LULUS") -> TIDAK LULUS | J46: =IF(J10>=60,"LULUS","TIDAK LULUS") -> TIDAK LULUS | K46: =IF(K10>=60,"LULUS","TIDAK LULUS") -> TIDAK LULUS | L46: =IF(L10>=60,"LULUS","TIDAK LULUS") -> TIDAK LULUS | N46: =SUM(D46:M46) -> 0
A47: 4 | B47: =B11 -> M. Fatan Azzamy Isma'il | C47: Utsmaniyyah III | D47: =IF(D11>=60,"LULUS","TIDAK LULUS") -> TIDAK LULUS | E47: =IF(E11>=60,"LULUS","TIDAK LULUS") -> TIDAK LULUS | F47: =IF(F11>=60,"LULUS","TIDAK LULUS") -> TIDAK LULUS | G47: =IF(G11>=60,"LULUS","TIDAK LULUS") -> TIDAK LULUS | H47: =IF(H11>=60,"LULUS","TIDAK LULUS") -> TIDAK LULUS | I47: =IF(I11>=60,"LULUS","TIDAK LULUS") -> TIDAK LULUS | J47: =IF(J11>=60,"LULUS","TIDAK LULUS") -> TIDAK LULUS | K47: =IF(K11>=60,"LULUS","TIDAK LULUS") -> TIDAK LULUS | L47: =IF(L11>=60,"LULUS","TIDAK LULUS") -> TIDAK LULUS | N47: =SUM(D47:M47) -> 0
A48: 5 | B48: =B12 -> M. Mahi Mutawakkil | C48: Utsmaniyyah III | D48: =IF(D12>=60,"LULUS","TIDAK LULUS") -> TIDAK LULUS | E48: =IF(E12>=60,"LULUS","TIDAK LULUS") -> TIDAK LULUS | F48: =IF(F12>=60,"LULUS","TIDAK LULUS") -> TIDAK LULUS | G48: =IF(G12>=60,"LULUS","TIDAK LULUS") -> TIDAK LULUS | H48: =IF(H12>=60,"LULUS","TIDAK LULUS") -> TIDAK LULUS | I48: =IF(I12>=60,"LULUS","TIDAK LULUS") -> TIDAK LULUS | J48: =IF(J12>=60,"LULUS","TIDAK LULUS") -> TIDAK LULUS | K48: =IF(K12>=60,"LULUS","TIDAK LULUS") -> TIDAK LULUS | L48: =IF(L12>=60,"LULUS","TIDAK LULUS") -> TIDAK LULUS | N48: =SUM(D48:M48) -> 0
A49: 6 | B49: =B13 -> Renoval Faiz Al Ghifari | C49: Utsmaniyyah III | D49: =IF(D13>=60,"LULUS","TIDAK LULUS") -> TIDAK LULUS | E49: =IF(E13>=60,"LULUS","TIDAK LULUS") -> TIDAK LULUS | F49: =IF(F13>=60,"LULUS","TIDAK LULUS") -> TIDAK LULUS | G49: =IF(G13>=60,"LULUS","TIDAK LULUS") -> TIDAK LULUS | H49: =IF(H13>=60,"LULUS","TIDAK LULUS") -> TIDAK LULUS | I49: =IF(I13>=60,"LULUS","TIDAK LULUS") -> TIDAK LULUS | J49: =IF(J13>=60,"LULUS","TIDAK LULUS") -> TIDAK LULUS | K49: =IF(K13>=60,"LULUS","TIDAK LULUS") -> TIDAK LULUS | L49: =IF(L13>=60,"LULUS","TIDAK LULUS") -> TIDAK LULUS | N49: =SUM(D49:M49) -> 0
...

Sheet tajwid
A1: DAFTAR NILAI UJIAN AKHIR
A2: LAJNAH MUROQOBAH YANBU'A LAMPUNG BARAT
L3: Materi | N3: : Tajwid
A5: No | B5: Nama | C5: Asal RTQ | D5: Nilai Catatan Kesalahan | N5: Total Nilai | O5: Keterangan
D6: Soal Teori | I6: Soal Evaluasi Tajwid
D7: 1 | E7: 2 | F7: 3 | G7: 4 | H7: 5 | I7: 1 | J7: 2 | K7: 3 | L7: 4 | M7: 5
A8: 1 | B8: =VLOOKUP(A8,'Data '!A2:J36,3,0) -> Ahmad Alhabib Ramadhan | C8: =VLOOKUP(A8,'Data '!A2:J36,2,0) -> Utsmaniyyah III | D8: 1 | N8: =SUM(D8:M8) -> 1 | Q8: =SUM(D8:M8) -> 1
A9: 2 | B9: =VLOOKUP(A9,'Data '!A3:J37,3,0) -> Aulia Zahra El Fikri | C9: =VLOOKUP(A9,'Data '!A3:J37,2,0) -> Utsmaniyyah III | D9: 2 | N9: =SUM(D9:M9) -> 2 | Q9: =SUM(D9:M9) -> 2
A10: 3 | B10: =VLOOKUP(A10,'Data '!A4:J38,3,0) -> Nur Habibi | C10: =VLOOKUP(A10,'Data '!A4:J38,2,0) -> Utsmaniyyah III | D10: 3 | N10: =SUM(D10:M10) -> 3 | Q10: =SUM(D10:M10) -> 3
A11: 4 | B11: =VLOOKUP(A11,'Data '!A5:J39,3,0) -> M. Fatan Azzamy Isma'il | C11: =VLOOKUP(A11,'Data '!A5:J39,2,0) -> Utsmaniyyah III | D11: 4 | N11: =SUM(D11:M11) -> 4 | Q11: =SUM(D11:M11) -> 4
A12: 5 | B12: =VLOOKUP(A12,'Data '!A6:J40,3,0) -> M. Mahi Mutawakkil | C12: =VLOOKUP(A12,'Data '!A6:J40,2,0) -> Utsmaniyyah III | D12: 5 | N12: =SUM(D12:M12) -> 5 | Q12: =SUM(D12:M12) -> 5
A13: 6 | B13: =VLOOKUP(A13,'Data '!A7:J41,3,0) -> Renoval Faiz Al Ghifari | C13: =VLOOKUP(A13,'Data '!A7:J41,2,0) -> Utsmaniyyah III | D13: 6 | N13: =SUM(D13:M13) -> 6 | Q13: =SUM(D13:M13) -> 6
A14: 7 | B14: =VLOOKUP(A14,'Data '!A8:J42,3,0) -> Sindi Wulandari | C14: =VLOOKUP(A14,'Data '!A8:J42,2,0) -> Utsmaniyyah III | D14: 7 | N14: =SUM(D14:M14) -> 7 | Q14: =SUM(D14:M14) -> 7
A15: 8 | B15: =VLOOKUP(A15,'Data '!A8:J43,3,0) -> 0 | C15: =VLOOKUP(A15,'Data '!A8:J43,2,0) -> 0 | D15: 8 | N15: =SUM(D15:M15) -> 8 | Q15: =SUM(D15:M15) -> 8
A16: 9 | B16: =VLOOKUP(A16,'Data '!A9:J44,3,0) -> 0 | C16: =VLOOKUP(A16,'Data '!A9:J44,2,0) -> 0 | N16: =SUM(D16:M16) -> 0 | Q16: =SUM(D16:M16) -> 0
A17: 10 | B17: =VLOOKUP(A17,'Data '!A10:J45,3,0) -> 0 | C17: =VLOOKUP(A17,'Data '!A10:J45,2,0) -> 0 | N17: =SUM(D17:M17) -> 0 | Q17: =SUM(D17:M17) -> 0
A18: 11 | B18: =VLOOKUP(A18,'Data '!A11:J46,3,0) -> 0 | C18: =VLOOKUP(A18,'Data '!A11:J46,2,0) -> 0 | N18: =SUM(D18:M18) -> 0 | Q18: =SUM(D18:M18) -> 0
A19: 12 | B19: =VLOOKUP(A19,'Data '!A12:J47,3,0) -> 0 | C19: =VLOOKUP(A19,'Data '!A12:J47,2,0) -> 0 | N19: =SUM(D19:M19) -> 0 | Q19: =SUM(D19:M19) -> 0
A20: 13 | B20: =VLOOKUP(A20,'Data '!A13:J48,3,0) -> 0 | C20: =VLOOKUP(A20,'Data '!A13:J48,2,0) -> 0 | N20: =SUM(D20:M20) -> 0 | Q20: =SUM(D20:M20) -> 0
A21: 14 | B21: =VLOOKUP(A21,'Data '!A14:J49,3,0) -> 0 | C21: =VLOOKUP(A21,'Data '!A14:J49,2,0) -> 0 | N21: =SUM(D21:M21) -> 0 | Q21: =SUM(D21:M21) -> 0
A22: 15 | B22: =VLOOKUP(A22,'Data '!A15:J50,3,0) -> 0 | C22: =VLOOKUP(A22,'Data '!A15:J50,2,0) -> 0 | N22: =SUM(D22:M22) -> 0 | Q22: =SUM(D22:M22) -> 0
A23: 16 | B23: =VLOOKUP(A23,'Data '!A16:J51,3,0) -> 0 | C23: =VLOOKUP(A23,'Data '!A16:J51,2,0) -> 0 | N23: =SUM(D23:M23) -> 0 | Q23: =SUM(D23:M23) -> 0
A24: 17 | B24: =VLOOKUP(A24,'Data '!A17:J52,3,0) -> 0 | C24: =VLOOKUP(A24,'Data '!A17:J52,2,0) -> 0 | N24: =SUM(D24:M24) -> 0 | Q24: =SUM(D24:M24) -> 0
A25: 18 | B25: =VLOOKUP(A25,'Data '!A18:J53,3,0) -> 0 | C25: =VLOOKUP(A25,'Data '!A18:J53,2,0) -> 0 | N25: =SUM(D25:M25) -> 0 | Q25: =SUM(D25:M25) -> 0
A26: 19 | B26: =VLOOKUP(A26,'Data '!A19:J54,3,0) -> 0 | C26: =VLOOKUP(A26,'Data '!A19:J54,2,0) -> 0 | N26: =SUM(D26:M26) -> 0 | Q26: =SUM(D26:M26) -> 0
A27: 20 | B27: =VLOOKUP(A27,'Data '!A20:J55,3,0) -> 0 | C27: =VLOOKUP(A27,'Data '!A20:J55,2,0) -> 0 | N27: =SUM(D27:M27) -> 0 | Q27: =SUM(D27:M27) -> 0
A28: 21 | B28: =VLOOKUP(A28,'Data '!A21:J56,3,0) -> 0 | C28: =VLOOKUP(A28,'Data '!A21:J56,2,0) -> 0 | N28: =SUM(D28:M28) -> 0 | Q28: =SUM(D28:M28) -> 0
K30: ='Data '!H38 -> Tambak Jaya, September 2025
K31: Penguji
K34: ……………………………………………..
A46: DAFTAR NILAI UJIAN AKHIR
A47: LAJNAH MUROQOBAH YANBU'A LAMPUNG BARAT
L48: Materi | N48: : Tauhid
A50: No | B50: Nama | C50: Asal RTQ | D50: Pertanyaan Nilai Max 1) | N50: Total Nilai | O50: Keterangan
D52: 1 | E52: 2 | F52: 3 | G52: 4 | H52: 5 | I52: 6 | J52: 7 | K52: 8 | L52: 9 | M52: 10
A53: 1 | B53: Ahmad Habiburrahman | C53: Utsmaniyyah III | Q53: =SUM(D53:M53) -> 0
A54: 2 | B54: Aulia Zahra El Fikri | C54: Utsmaniyyah III | Q54: =SUM(D54:M54) -> 0
A55: 3 | B55: Nur Habibi | C55: Utsmaniyyah III | Q55: =SUM(D55:M55) -> 0
A56: 4 | B56: M. Fatan Azzamy Isma'il | C56: Utsmaniyyah III | Q56: =SUM(D56:M56) -> 0
A57: 5 | B57: M. Mahi Mutawakkil | C57: Utsmaniyyah III | Q57: =SUM(D57:M57) -> 0
...

Sheet tauhid
A1: DAFTAR NILAI UJIAN AKHIR
A2: LAJNAH MUROQOBAH YANBU'A LAMPUNG BARAT
L3: Materi | N3: : Tajwid
A5: No | B5: Nama | C5: Asal RTQ | D5: Nilai Catatan Kesalahan | N5: Total Nilai | O5: Keterangan
D6: Soal Teori | I6: Soal Evaluasi Tajwid
D7: 1 | E7: 2 | F7: 3 | G7: 4 | H7: 5 | I7: 1 | J7: 2 | K7: 3 | L7: 4 | M7: 5
A8: 1 | B8: =VLOOKUP(A8,'Data '!A2:J36,3,0) -> Ahmad Alhabib Ramadhan | C8: =VLOOKUP(A8,'Data '!A2:J36,2,0) -> Utsmaniyyah III | N8: =SUM(D8:M8) -> 0 | Q8: =SUM(D8:M8) -> 0
A9: 2 | B9: =VLOOKUP(A9,'Data '!A3:J37,3,0) -> Aulia Zahra El Fikri | C9: =VLOOKUP(A9,'Data '!A3:J37,2,0) -> Utsmaniyyah III | N9: =SUM(D9:M9) -> 0 | Q9: =SUM(D9:M9) -> 0
A10: 3 | B10: =VLOOKUP(A10,'Data '!A4:J38,3,0) -> Nur Habibi | C10: =VLOOKUP(A10,'Data '!A4:J38,2,0) -> Utsmaniyyah III | N10: =SUM(D10:M10) -> 0 | Q10: =SUM(D10:M10) -> 0
A11: 4 | B11: =VLOOKUP(A11,'Data '!A5:J39,3,0) -> M. Fatan Azzamy Isma'il | C11: =VLOOKUP(A11,'Data '!A5:J39,2,0) -> Utsmaniyyah III | N11: =SUM(D11:M11) -> 0 | Q11: =SUM(D11:M11) -> 0
A12: 5 | B12: =VLOOKUP(A12,'Data '!A6:J40,3,0) -> M. Mahi Mutawakkil | C12: =VLOOKUP(A12,'Data '!A6:J40,2,0) -> Utsmaniyyah III | N12: =SUM(D12:M12) -> 0 | Q12: =SUM(D12:M12) -> 0
A13: 6 | B13: =VLOOKUP(A13,'Data '!A7:J41,3,0) -> Renoval Faiz Al Ghifari | C13: =VLOOKUP(A13,'Data '!A7:J41,2,0) -> Utsmaniyyah III | N13: =SUM(D13:M13) -> 0 | Q13: =SUM(D13:M13) -> 0
A14: 7 | B14: =VLOOKUP(A14,'Data '!A8:J42,3,0) -> Sindi Wulandari | C14: =VLOOKUP(A14,'Data '!A8:J42,2,0) -> Utsmaniyyah III | N14: =SUM(D14:M14) -> 0 | Q14: =SUM(D14:M14) -> 0
A15: 8 | B15: =VLOOKUP(A15,'Data '!A8:J43,3,0) -> 0 | C15: =VLOOKUP(A15,'Data '!A8:J43,2,0) -> 0 | N15: =SUM(D15:M15) -> 0 | Q15: =SUM(D15:M15) -> 0
A16: 9 | B16: =VLOOKUP(A16,'Data '!A9:J44,3,0) -> 0 | C16: =VLOOKUP(A16,'Data '!A9:J44,2,0) -> 0 | N16: =SUM(D16:M16) -> 0 | Q16: =SUM(D16:M16) -> 0
A17: 10 | B17: =VLOOKUP(A17,'Data '!A10:J45,3,0) -> 0 | C17: =VLOOKUP(A17,'Data '!A10:J45,2,0) -> 0 | N17: =SUM(D17:M17) -> 0 | Q17: =SUM(D17:M17) -> 0
A18: 11 | B18: =VLOOKUP(A18,'Data '!A11:J46,3,0) -> 0 | C18: =VLOOKUP(A18,'Data '!A11:J46,2,0) -> 0 | N18: =SUM(D18:M18) -> 0 | Q18: =SUM(D18:M18) -> 0
A19: 12 | B19: =VLOOKUP(A19,'Data '!A12:J47,3,0) -> 0 | C19: =VLOOKUP(A19,'Data '!A12:J47,2,0) -> 0 | N19: =SUM(D19:M19) -> 0 | Q19: =SUM(D19:M19) -> 0
A20: 13 | B20: =VLOOKUP(A20,'Data '!A13:J48,3,0) -> 0 | C20: =VLOOKUP(A20,'Data '!A13:J48,2,0) -> 0 | N20: =SUM(D20:M20) -> 0 | Q20: =SUM(D20:M20) -> 0
A21: 14 | B21: =VLOOKUP(A21,'Data '!A14:J49,3,0) -> 0 | C21: =VLOOKUP(A21,'Data '!A14:J49,2,0) -> 0 | N21: =SUM(D21:M21) -> 0 | Q21: =SUM(D21:M21) -> 0
A22: 15 | B22: =VLOOKUP(A22,'Data '!A15:J50,3,0) -> 0 | C22: =VLOOKUP(A22,'Data '!A15:J50,2,0) -> 0 | N22: =SUM(D22:M22) -> 0 | Q22: =SUM(D22:M22) -> 0
A23: 16 | B23: =VLOOKUP(A23,'Data '!A16:J51,3,0) -> 0 | C23: =VLOOKUP(A23,'Data '!A16:J51,2,0) -> 0 | N23: =SUM(D23:M23) -> 0 | Q23: =SUM(D23:M23) -> 0
A24: 17 | B24: =VLOOKUP(A24,'Data '!A17:J52,3,0) -> 0 | C24: =VLOOKUP(A24,'Data '!A17:J52,2,0) -> 0 | N24: =SUM(D24:M24) -> 0 | Q24: =SUM(D24:M24) -> 0
A25: 18 | B25: =VLOOKUP(A25,'Data '!A18:J53,3,0) -> 0 | C25: =VLOOKUP(A25,'Data '!A18:J53,2,0) -> 0 | N25: =SUM(D25:M25) -> 0 | Q25: =SUM(D25:M25) -> 0
A26: 19 | B26: =VLOOKUP(A26,'Data '!A19:J54,3,0) -> 0 | C26: =VLOOKUP(A26,'Data '!A19:J54,2,0) -> 0 | N26: =SUM(D26:M26) -> 0 | Q26: =SUM(D26:M26) -> 0
... A28: 21 | B28: =VLOOKUP(A28,'Data '!A21:J56,3,0) -> 0 | C28: =VLOOKUP(A28,'Data '!A21:J56,2,0) -> 0 | N28: =SUM(D28:M28) -> 0 | Q28: =SUM(D28:M28) -> 0
K30: ='Data '!H38 -> Tambak Jaya, September 2025
K31: Penguji
K34: ……………………………………………..
A46: DAFTAR NILAI UJIAN AKHIR
A47: LAJNAH MUROQOBAH YANBU'A LAMPUNG BARAT
L48: Materi | N48: : Tauhid
A50: No | B50: Nama | C50: Asal RTQ | D50: Pertanyaan Nilai Max 1) | N50: Total Nilai | O50: Keterangan
D52: 1 | E52: 2 | F52: 3 | G52: 4 | H52: 5 | I52: 6 | J52: 7 | K52: 8 | L52: 9 | M52: 10
A53: 1 | B53: Ahmad Habiburrahman | C53: Utsmaniyyah III | Q53: =SUM(D53:M53) -> 0
A54: 2 | B54: Aulia Zahra El Fikri | C54: Utsmaniyyah III | Q54: =SUM(D54:M54) -> 0
A55: 3 | B55: Nur Habibi | C55: Utsmaniyyah III | Q55: =SUM(D55:M55) -> 0
A56: 4 | B56: M. Fatan Azzamy Isma'il | C56: Utsmaniyyah III | Q56: =SUM(D56:M56) -> 0
A57: 5 | B57: M. Mahi Mutawakkil | C57: Utsmaniyyah III | Q57: =SUM(D57:M57) -> 0
A58: 6 | B58: Muhammad Rozikin | C58: Utsmaniyyah III | Q58: =SUM(D58:M58) -> 0
...

Sheet kitabah
A1: DAFTAR NILAI UJIAN AKHIR
A2: LAJNAH MUROQOBAH YANBU'A LAMPUNG BARAT
L3: Materi | N3: : Kitabah
A5: No | B5: Nama | C5: Asal RTQ | D5: Nilai Catatan Kesalahan | N5: Total Nilai | O5: Keterangan
D7: 1 | E7: 2 | F7: 3 | G7: 4 | H7: 5 | I7: 6 | J7: 7 | K7: 8 | L7: 9 | M7: 10
A8: 1 | B8: =VLOOKUP(A8,'Data '!A2:J36,3,0) -> Ahmad Alhabib Ramadhan | C8: =VLOOKUP(A8,'Data '!A2:J36,2,0) -> Utsmaniyyah III | N8: =SUM(D8:M8) -> 0 | S8: =SUM(D8:M8) -> 0
A9: 2 | B9: =VLOOKUP(A9,'Data '!A3:J37,3,0) -> Aulia Zahra El Fikri | C9: =VLOOKUP(A9,'Data '!A3:J37,2,0) -> Utsmaniyyah III | N9: =SUM(D9:M9) -> 0 | S9: =SUM(D9:M9) -> 0
A10: 3 | B10: =VLOOKUP(A10,'Data '!A4:J38,3,0) -> Nur Habibi | C10: =VLOOKUP(A10,'Data '!A4:J38,2,0) -> Utsmaniyyah III | N10: =SUM(D10:M10) -> 0 | S10: =SUM(D10:M10) -> 0
A11: 4 | B11: =VLOOKUP(A11,'Data '!A5:J39,3,0) -> M. Fatan Azzamy Isma'il | C11: =VLOOKUP(A11,'Data '!A5:J39,2,0) -> Utsmaniyyah III | N11: =SUM(D11:M11) -> 0 | S11: =SUM(D11:M11) -> 0
A12: 5 | B12: =VLOOKUP(A12,'Data '!A6:J40,3,0) -> M. Mahi Mutawakkil | C12: =VLOOKUP(A12,'Data '!A6:J40,2,0) -> Utsmaniyyah III | N12: =SUM(D12:M12) -> 0 | S12: =SUM(D12:M12) -> 0
A13: 6 | B13: =VLOOKUP(A13,'Data '!A7:J41,3,0) -> Renoval Faiz Al Ghifari | C13: =VLOOKUP(A13,'Data '!A7:J41,2,0) -> Utsmaniyyah III | N13: =SUM(D13:M13) -> 0 | S13: =SUM(D13:M13) -> 0
A14: 7 | B14: =VLOOKUP(A14,'Data '!A8:J42,3,0) -> Sindi Wulandari | C14: =VLOOKUP(A14,'Data '!A8:J42,2,0) -> Utsmaniyyah III | N14: =SUM(D14:M14) -> 0 | S14: =SUM(D14:M14) -> 0
A15: 8 | B15: =VLOOKUP(A15,'Data '!A8:J43,3,0) -> 0 | C15: =VLOOKUP(A15,'Data '!A8:J43,2,0) -> 0 | N15: =SUM(D15:M15) -> 0 | S15: =SUM(D15:M15) -> 0
A16: 9 | B16: =VLOOKUP(A16,'Data '!A9:J44,3,0) -> 0 | C16: =VLOOKUP(A16,'Data '!A9:J44,2,0) -> 0 | N16: =SUM(D16:M16) -> 0 | S16: =SUM(D16:M16) -> 0
A17: 10 | B17: =VLOOKUP(A17,'Data '!A10:J45,3,0) -> 0 | C17: =VLOOKUP(A17,'Data '!A10:J45,2,0) -> 0 | N17: =SUM(D17:M17) -> 0 | S17: =SUM(D17:M17) -> 0
A18: 11 | B18: =VLOOKUP(A18,'Data '!A11:J46,3,0) -> 0 | C18: =VLOOKUP(A18,'Data '!A11:J46,2,0) -> 0 | N18: =SUM(D18:M18) -> 0 | S18: =SUM(D18:M18) -> 0
A19: 12 | B19: =VLOOKUP(A19,'Data '!A12:J47,3,0) -> 0 | C19: =VLOOKUP(A19,'Data '!A12:J47,2,0) -> 0 | N19: =SUM(D19:M19) -> 0 | S19: =SUM(D19:M19) -> 0
A20: 13 | B20: =VLOOKUP(A20,'Data '!A13:J48,3,0) -> 0 | C20: =VLOOKUP(A20,'Data '!A13:J48,2,0) -> 0 | N20: =SUM(D20:M20) -> 0 | S20: =SUM(D20:M20) -> 0
A21: 14 | B21: =VLOOKUP(A21,'Data '!A14:J49,3,0) -> 0 | C21: =VLOOKUP(A21,'Data '!A14:J49,2,0) -> 0 | N21: =SUM(D21:M21) -> 0 | S21: =SUM(D21:M21) -> 0
A22: 15 | B22: =VLOOKUP(A22,'Data '!A15:J50,3,0) -> 0 | C22: =VLOOKUP(A22,'Data '!A15:J50,2,0) -> 0 | N22: =SUM(D22:M22) -> 0 | S22: =SUM(D22:M22) -> 0
A23: 16 | B23: =VLOOKUP(A23,'Data '!A16:J51,3,0) -> 0 | C23: =VLOOKUP(A23,'Data '!A16:J51,2,0) -> 0 | N23: =SUM(D23:M23) -> 0 | S23: =SUM(D23:M23) -> 0
A24: 17 | B24: =VLOOKUP(A24,'Data '!A17:J52,3,0) -> 0 | C24: =VLOOKUP(A24,'Data '!A17:J52,2,0) -> 0 | N24: =SUM(D24:M24) -> 0 | S24: =SUM(D24:M24) -> 0
A25: 18 | B25: =VLOOKUP(A25,'Data '!A18:J53,3,0) -> 0 | C25: =VLOOKUP(A25,'Data '!A18:J53,2,0) -> 0 | N25: =SUM(D25:M25) -> 0 | S25: =SUM(D25:M25) -> 0
A26: 19 | B26: =VLOOKUP(A26,'Data '!A19:J54,3,0) -> 0 | C26: =VLOOKUP(A26,'Data '!A19:J54,2,0) -> 0 | N26: =SUM(D26:M26) -> 0 | S26: =SUM(D26:M26) -> 0
... A28: 21 | B28: =VLOOKUP(A28,'Data '!A21:J56,3,0) -> 0 | C28: =VLOOKUP(A28,'Data '!A21:J56,2,0) -> 0 | N28: =SUM(D28:M28) -> 0 | S28: =SUM(D28:M28) -> 0
K30: ='Data '!H38 -> Tambak Jaya, September 2025
K31: Penguji
K34: ……………………………………………..

Sheet Wudlu
A1: DAFTAR NILAI UJIAN AKHIR
A2: LAJNAH MUROQOBAH YANBU'A LAMPUNG BARAT
L3: Materi | N3: : Praktik Wudlu
A5: No | B5: Nama | C5: Asal RTQ | D5: Nilai Gerakan Wudlu Nilai Max 2) | N5: Total Nilai | O5: Keterangan
D7: Niat | E7: 1 | F7: 2 | G7: 3 | H7: 4 | I7: 5 | J7: 6 | K7: Do'a
A8: 1 | B8: =VLOOKUP(A8,'Data '!A2:J36,3,0) -> Ahmad Alhabib Ramadhan | C8: =VLOOKUP(A8,'Data '!A2:J36,2,0) -> Utsmaniyyah III | N8: =SUM(D8:M8) -> 0 | R8: 0.8 | S8: 0.8 | T8: =SUM(D8:K8) -> 0
A9: 2 | B9: =VLOOKUP(A9,'Data '!A3:J37,3,0) -> Aulia Zahra El Fikri | C9: =VLOOKUP(A9,'Data '!A3:J37,2,0) -> Utsmaniyyah III | N9: =SUM(D9:M9) -> 0 | R9: 0.9 | S9: 0.8 | T9: =SUM(D9:K9) -> 0
A10: 3 | B10: =VLOOKUP(A10,'Data '!A4:J38,3,0) -> Nur Habibi | C10: =VLOOKUP(A10,'Data '!A4:J38,2,0) -> Utsmaniyyah III | N10: =SUM(D10:M10) -> 0 | R10: 0.8 | S10: 0.8 | T10: =SUM(D10:K10) -> 0
A11: 4 | B11: =VLOOKUP(A11,'Data '!A5:J39,3,0) -> M. Fatan Azzamy Isma'il | C11: =VLOOKUP(A11,'Data '!A5:J39,2,0) -> Utsmaniyyah III | N11: =SUM(D11:M11) -> 0 | R11: 1 | S11: 1 | T11: =SUM(D11:K11) -> 0
A12: 5 | B12: =VLOOKUP(A12,'Data '!A6:J40,3,0) -> M. Mahi Mutawakkil | C12: =VLOOKUP(A12,'Data '!A6:J40,2,0) -> Utsmaniyyah III | N12: =SUM(D12:M12) -> 0 | R12: 0.9 | S12: 0.9 | T12: =SUM(D12:K12) -> 0
A13: 6 | B13: =VLOOKUP(A13,'Data '!A7:J41,3,0) -> Renoval Faiz Al Ghifari | C13: =VLOOKUP(A13,'Data '!A7:J41,2,0) -> Utsmaniyyah III | N13: =SUM(D13:M13) -> 0 | R13: 0.8 | S13: 0.8 | T13: =SUM(D13:K13) -> 0
A14: 7 | B14: =VLOOKUP(A14,'Data '!A8:J42,3,0) -> Sindi Wulandari | C14: =VLOOKUP(A14,'Data '!A8:J42,2,0) -> Utsmaniyyah III | N14: =SUM(D14:M14) -> 0 | R14: 1 | S14: 1 | T14: =SUM(D14:K14) -> 0
A15: 8 | B15: =VLOOKUP(A15,'Data '!A8:J43,3,0) -> 0 | C15: =VLOOKUP(A15,'Data '!A8:J43,2,0) -> 0 | N15: =SUM(D15:M15) -> 0 | R15: 1 | S15: 1 | T15: =SUM(D15:K15) -> 0
A16: 9 | B16: =VLOOKUP(A16,'Data '!A9:J44,3,0) -> 0 | C16: =VLOOKUP(A16,'Data '!A9:J44,2,0) -> 0 | N16: =SUM(D16:M16) -> 0 | R16: 1 | S16: 1 | T16: =SUM(D16:K16) -> 0
A17: 10 | B17: =VLOOKUP(A17,'Data '!A10:J45,3,0) -> 0 | C17: =VLOOKUP(A17,'Data '!A10:J45,2,0) -> 0 | N17: =SUM(D17:M17) -> 0 | R17: 1 | S17: 1 | T17: =SUM(D17:K17) -> 0
A18: 11 | B18: =VLOOKUP(A18,'Data '!A11:J46,3,0) -> 0 | C18: =VLOOKUP(A18,'Data '!A11:J46,2,0) -> 0 | N18: =SUM(D18:M18) -> 0 | R18: 0.9 | S18: 0.9 | T18: =SUM(D18:K18) -> 0
A19: 12 | B19: =VLOOKUP(A19,'Data '!A12:J47,3,0) -> 0 | C19: =VLOOKUP(A19,'Data '!A12:J47,2,0) -> 0 | N19: =SUM(D19:M19) -> 0 | R19: 1 | S19: 0.9 | T19: =SUM(D19:K19) -> 0
A20: 13 | B20: =VLOOKUP(A20,'Data '!A13:J48,3,0) -> 0 | C20: =VLOOKUP(A20,'Data '!A13:J48,2,0) -> 0 | N20: =SUM(D20:M20) -> 0 | R20: 0.9 | S20: 1 | T20: =SUM(D20:K20) -> 0
A21: 14 | B21: =VLOOKUP(A21,'Data '!A14:J49,3,0) -> 0 | C21: =VLOOKUP(A21,'Data '!A14:J49,2,0) -> 0 | N21: =SUM(D21:M21) -> 0 | R21: 2 | S21: 1 | T21: =SUM(D21:K21) -> 0
A22: 15 | B22: =VLOOKUP(A22,'Data '!A15:J50,3,0) -> 0 | C22: =VLOOKUP(A22,'Data '!A15:J50,2,0) -> 0 | N22: =SUM(D22:M22) -> 0 | R22: 1 | S22: 1 | T22: =SUM(D22:K22) -> 0
A23: 16 | B23: =VLOOKUP(A23,'Data '!A16:J51,3,0) -> 0 | C23: =VLOOKUP(A23,'Data '!A16:J51,2,0) -> 0 | N23: =SUM(D23:M23) -> 0 | R23: 0.9 | S23: 0.8 | T23: =SUM(D23:K23) -> 0
A24: 17 | B24: =VLOOKUP(A24,'Data '!A17:J52,3,0) -> 0 | C24: =VLOOKUP(A24,'Data '!A17:J52,2,0) -> 0 | N24: =SUM(D24:M24) -> 0 | R24: 1 | S24: 1 | T24: =SUM(D24:K24) -> 0
A25: 18 | B25: =VLOOKUP(A25,'Data '!A18:J53,3,0) -> 0 | C25: =VLOOKUP(A25,'Data '!A18:J53,2,0) -> 0 | N25: =SUM(D25:M25) -> 0 | R25: 0.8 | S25: 0.8 | T25: =SUM(D25:K25) -> 0
A26: 19 | B26: =VLOOKUP(A26,'Data '!A19:J54,3,0) -> 0 | C26: =VLOOKUP(A26,'Data '!A19:J54,2,0) -> 0 | N26: =SUM(D26:M26) -> 0 | R26: 0.8 | S26: 0.7 | T26: =SUM(D26:K26) -> 0
... A28: 21 | B28: =VLOOKUP(A28,'Data '!A21:J56,3,0) -> 0 | C28: =VLOOKUP(A28,'Data '!A21:J56,2,0) -> 0 | N28: =SUM(D28:M28) -> 0 | R28: 0.6 | S28: 0.8 | T28: =SUM(D28:K28) -> 0
K30: ='Data '!H38 -> Tambak Jaya, September 2025
K31: Penguji
K34: ……………………………………………..

Sheet Fasolatan
A1: DAFTAR NILAI UJIAN AKHIR
A2: LAJNAH MUROQOBAH YANBU'A LAMPUNG BARAT
L3: Materi | N3: : Praktik Sholat
A5: No | B5: Nama | C5: Asal RTQ | D5: Rincian Nilai | N5: Total Nilai | O5: Keterangan
D6: Niat dan Berdiri | E6: Takbir dan Iftitah | F6: Fatihah | G6: Ruku' | H6: I'tidal dan Qunud | I6: Sujud | J6: iftirosy | K6: Tawaruk | L6: Tasyahud | M6: Salam
D7: 1 | E7: 1 | F7: 1,5 | G7: 0,5 | H7: 1 | I7: 0,5 | J7: 0,5 | K7: 1 | L7: 1,5 | M7: 0,5
A8: 1 | B8: =VLOOKUP(A8,'Data '!A2:J36,3,0) -> Ahmad Alhabib Ramadhan | C8: =VLOOKUP(A8,'Data '!A2:J36,2,0) -> Utsmaniyyah III | N8: =SUM(D8:M8) -> 0 | R8: =SUM(D8:M8) -> 0 | S8: =IF(R8>=70,"LULUS","TIDAK LULUS") -> TIDAK LULUS
A9: 2 | B9: =VLOOKUP(A9,'Data '!A3:J37,3,0) -> Aulia Zahra El Fikri | C9: =VLOOKUP(A9,'Data '!A3:J37,2,0) -> Utsmaniyyah III | N9: =SUM(D9:M9) -> 0 | R9: =SUM(D9:M9) -> 0 | S9: =IF(R9>=70,"LULUS","TIDAK LULUS") -> TIDAK LULUS
A10: 3 | B10: =VLOOKUP(A10,'Data '!A4:J38,3,0) -> Nur Habibi | C10: =VLOOKUP(A10,'Data '!A4:J38,2,0) -> Utsmaniyyah III | N10: =SUM(D10:M10) -> 0 | R10: =SUM(D10:M10) -> 0 | S10: =IF(R10>=70,"LULUS","TIDAK LULUS") -> TIDAK LULUS
A11: 4 | B11: =VLOOKUP(A11,'Data '!A5:J39,3,0) -> M. Fatan Azzamy Isma'il | C11: =VLOOKUP(A11,'Data '!A5:J39,2,0) -> Utsmaniyyah III | N11: =SUM(D11:M11) -> 0 | R11: =SUM(D11:M11) -> 0 | S11: =IF(R11>=70,"LULUS","TIDAK LULUS") -> TIDAK LULUS
A12: 5 | B12: =VLOOKUP(A12,'Data '!A6:J40,3,0) -> M. Mahi Mutawakkil | C12: =VLOOKUP(A12,'Data '!A6:J40,2,0) -> Utsmaniyyah III | N12: =SUM(D12:M12) -> 0 | R12: =SUM(D12:M12) -> 0 | S12: =IF(R12>=70,"LULUS","TIDAK LULUS") -> TIDAK LULUS
A13: 6 | B13: =VLOOKUP(A13,'Data '!A7:J41,3,0) -> Renoval Faiz Al Ghifari | C13: =VLOOKUP(A13,'Data '!A7:J41,2,0) -> Utsmaniyyah III | N13: =SUM(D13:M13) -> 0 | R13: =SUM(D13:M13) -> 0 | S13: =IF(R13>=70,"LULUS","TIDAK LULUS") -> TIDAK LULUS
A14: 7 | B14: =VLOOKUP(A14,'Data '!A8:J42,3,0) -> Sindi Wulandari | C14: =VLOOKUP(A14,'Data '!A8:J42,2,0) -> Utsmaniyyah III | N14: =SUM(D14:M14) -> 0 | R14: =SUM(D14:M14) -> 0 | S14: =IF(R14>=70,"LULUS","TIDAK LULUS") -> TIDAK LULUS
A15: 8 | B15: =VLOOKUP(A15,'Data '!A8:J43,3,0) -> 0 | C15: =VLOOKUP(A15,'Data '!A8:J43,2,0) -> 0 | N15: =SUM(D15:M15) -> 0 | R15: =SUM(D15:M15) -> 0 | S15: =IF(R15>=70,"LULUS","TIDAK LULUS") -> TIDAK LULUS
A16: 9 | B16: =VLOOKUP(A16,'Data '!A9:J44,3,0) -> 0 | C16: =VLOOKUP(A16,'Data '!A9:J44,2,0) -> 0 | N16: =SUM(D16:M16) -> 0 | R16: =SUM(D16:M16) -> 0 | S16: =IF(R16>=70,"LULUS","TIDAK LULUS") -> TIDAK LULUS
A17: 10 | B17: =VLOOKUP(A17,'Data '!A10:J45,3,0) -> 0 | C17: =VLOOKUP(A17,'Data '!A10:J45,2,0) -> 0 | N17: =SUM(D17:M17) -> 0 | R17: =SUM(D17:M17) -> 0 | S17: =IF(R17>=70,"LULUS","TIDAK LULUS") -> TIDAK LULUS
A18: 11 | B18: =VLOOKUP(A18,'Data '!A11:J46,3,0) -> 0 | C18: =VLOOKUP(A18,'Data '!A11:J46,2,0) -> 0 | N18: =SUM(D18:M18) -> 0 | R18: =SUM(D18:M18) -> 0 | S18: =IF(R18>=70,"LULUS","TIDAK LULUS") -> TIDAK LULUS
A19: 12 | B19: =VLOOKUP(A19,'Data '!A12:J47,3,0) -> 0 | C19: =VLOOKUP(A19,'Data '!A12:J47,2,0) -> 0 | N19: =SUM(D19:M19) -> 0 | R19: =SUM(D19:M19) -> 0 | S19: =IF(R19>=70,"LULUS","TIDAK LULUS") -> TIDAK LULUS
A20: 13 | B20: =VLOOKUP(A20,'Data '!A13:J48,3,0) -> 0 | C20: =VLOOKUP(A20,'Data '!A13:J48,2,0) -> 0 | N20: =SUM(D20:M20) -> 0 | R20: =SUM(D20:M20) -> 0 | S20: =IF(R20>=70,"LULUS","TIDAK LULUS") -> TIDAK LULUS
A21: 14 | B21: =VLOOKUP(A21,'Data '!A14:J49,3,0) -> 0 | C21: =VLOOKUP(A21,'Data '!A14:J49,2,0) -> 0 | N21: =SUM(D21:M21) -> 0 | R21: =SUM(D21:M21) -> 0 | S21: =IF(R21>=70,"LULUS","TIDAK LULUS") -> TIDAK LULUS
A22: 15 | B22: =VLOOKUP(A22,'Data '!A15:J50,3,0) -> 0 | C22: =VLOOKUP(A22,'Data '!A15:J50,2,0) -> 0 | N22: =SUM(D22:M22) -> 0 | R22: =SUM(D22:M22) -> 0 | S22: =IF(R22>=70,"LULUS","TIDAK LULUS") -> TIDAK LULUS
A23: 16 | B23: =VLOOKUP(A23,'Data '!A16:J51,3,0) -> 0 | C23: =VLOOKUP(A23,'Data '!A16:J51,2,0) -> 0 | N23: =SUM(D23:M23) -> 0 | R23: =SUM(D23:M23) -> 0 | S23: =IF(R23>=70,"LULUS","TIDAK LULUS") -> TIDAK LULUS
A24: 17 | B24: =VLOOKUP(A24,'Data '!A17:J52,3,0) -> 0 | C24: =VLOOKUP(A24,'Data '!A17:J52,2,0) -> 0 | N24: =SUM(D24:M24) -> 0 | R24: =SUM(D24:M24) -> 0 | S24: =IF(R24>=70,"LULUS","TIDAK LULUS") -> TIDAK LULUS
A25: 18 | B25: =VLOOKUP(A25,'Data '!A18:J53,3,0) -> 0 | C25: =VLOOKUP(A25,'Data '!A18:J53,2,0) -> 0 | N25: =SUM(D25:M25) -> 0 | R25: =SUM(D25:M25) -> 0 | S25: =IF(R25>=70,"LULUS","TIDAK LULUS") -> TIDAK LULUS
A26: 19 | B26: =VLOOKUP(A26,'Data '!A19:J54,3,0) -> 0 | C26: =VLOOKUP(A26,'Data '!A19:J54,2,0) -> 0 | N26: =SUM(D26:M26) -> 0 | R26: =SUM(D26:M26) -> 0 | S26: =IF(R26>=70,"LULUS","TIDAK LULUS") -> TIDAK LULUS
... A28: 21 | B28: =VLOOKUP(A28,'Data '!A21:J56,3,0) -> 0 | C28: =VLOOKUP(A28,'Data '!A21:J56,2,0) -> 0 | N28: =SUM(D28:M28) -> 0 | R28: =SUM(D28:M28) -> 0 | S28: =IF(R28>=70,"LULUS","TIDAK LULUS") -> TIDAK LULUS
K30: ='Data '!H38 -> Tambak Jaya, September 2025
K31: Penguji
K33: ……………………………………………..

Sheet doa harian
A1: DAFTAR NILAI UJIAN AKHIR
A2: LAJNAH MUROQOBAH YANBU'A LAMPUNG BARAT
L3: Materi | N3: : Doa Harian
A5: No | B5: Nama | C5: Asal RTQ | D5: Doa Harian | N5: Total Nilai | O5: Keterangan
D7: 1 | E7: 2 | F7: 3 | G7: 4 | H7: 5 | I7: 6 | J7: 7 | K7: 8 | L7: 9 | M7: 10
A8: 1 | B8: =VLOOKUP(A8,'Data '!A2:J36,3,0) -> Ahmad Alhabib Ramadhan | C8: =VLOOKUP(A8,'Data '!A2:J36,2,0) -> Utsmaniyyah III | N8: =SUM(D8:M8) -> 0 | R8: 0.8 | S8: 0.8 | T8: =SUM(D8:K8) -> 0
A9: 2 | B9: =VLOOKUP(A9,'Data '!A3:J37,3,0) -> Aulia Zahra El Fikri | C9: =VLOOKUP(A9,'Data '!A3:J37,2,0) -> Utsmaniyyah III | N9: =SUM(D9:M9) -> 0 | R9: 0.9 | S9: 0.8 | T9: =SUM(D9:K9) -> 0
A10: 3 | B10: =VLOOKUP(A10,'Data '!A4:J38,3,0) -> Nur Habibi | C10: =VLOOKUP(A10,'Data '!A4:J38,2,0) -> Utsmaniyyah III | N10: =SUM(D10:M10) -> 0 | R10: 0.8 | S10: 0.8 | T10: =SUM(D10:K10) -> 0
A11: 4 | B11: =VLOOKUP(A11,'Data '!A5:J39,3,0) -> M. Fatan Azzamy Isma'il | C11: =VLOOKUP(A11,'Data '!A5:J39,2,0) -> Utsmaniyyah III | N11: =SUM(D11:M11) -> 0 | R11: 1 | S11: 1 | T11: =SUM(D11:K11) -> 0
A12: 5 | B12: =VLOOKUP(A12,'Data '!A6:J40,3,0) -> M. Mahi Mutawakkil | C12: =VLOOKUP(A12,'Data '!A6:J40,2,0) -> Utsmaniyyah III | N12: =SUM(D12:M12) -> 0 | R12: 0.9 | S12: 0.9 | T12: =SUM(D12:K12) -> 0
A13: 6 | B13: =VLOOKUP(A13,'Data '!A7:J41,3,0) -> Renoval Faiz Al Ghifari | C13: =VLOOKUP(A13,'Data '!A7:J41,2,0) -> Utsmaniyyah III | N13: =SUM(D13:M13) -> 0 | R13: 0.8 | S13: 0.8 | T13: =SUM(D13:K13) -> 0
A14: 7 | B14: =VLOOKUP(A14,'Data '!A8:J42,3,0) -> Sindi Wulandari | C14: =VLOOKUP(A14,'Data '!A8:J42,2,0) -> Utsmaniyyah III | N14: =SUM(D14:M14) -> 0 | R14: 1 | S14: 1 | T14: =SUM(D14:K14) -> 0
A15: 8 | B15: =VLOOKUP(A15,'Data '!A8:J43,3,0) -> 0 | C15: =VLOOKUP(A15,'Data '!A8:J43,2,0) -> 0 | N15: =SUM(D15:M15) -> 0 | R15: 1 | S15: 1 | T15: =SUM(D15:K15) -> 0
A16: 9 | B16: =VLOOKUP(A16,'Data '!A9:J44,3,0) -> 0 | C16: =VLOOKUP(A16,'Data '!A9:J44,2,0) -> 0 | N16: =SUM(D16:M16) -> 0 | R16: 1 | S16: 1 | T16: =SUM(D16:K16) -> 0
A17: 10 | B17: =VLOOKUP(A17,'Data '!A10:J45,3,0) -> 0 | C17: =VLOOKUP(A17,'Data '!A10:J45,2,0) -> 0 | N17: =SUM(D17:M17) -> 0 | R17: 1 | S17: 1 | T17: =SUM(D17:K17) -> 0
A18: 11 | B18: =VLOOKUP(A18,'Data '!A11:J46,3,0) -> 0 | C18: =VLOOKUP(A18,'Data '!A11:J46,2,0) -> 0 | N18: =SUM(D18:M18) -> 0 | R18: 0.9 | S18: 0.9 | T18: =SUM(D18:K18) -> 0
A19: 12 | B19: =VLOOKUP(A19,'Data '!A12:J47,3,0) -> 0 | C19: =VLOOKUP(A19,'Data '!A12:J47,2,0) -> 0 | N19: =SUM(D19:M19) -> 0 | R19: 1 | S19: 0.9 | T19: =SUM(D19:K19) -> 0
A20: 13 | B20: =VLOOKUP(A20,'Data '!A13:J48,3,0) -> 0 | C20: =VLOOKUP(A20,'Data '!A13:J48,2,0) -> 0 | N20: =SUM(D20:M20) -> 0 | R20: 0.9 | S20: 1 | T20: =SUM(D20:K20) -> 0
A21: 14 | B21: =VLOOKUP(A21,'Data '!A14:J49,3,0) -> 0 | C21: =VLOOKUP(A21,'Data '!A14:J49,2,0) -> 0 | N21: =SUM(D21:M21) -> 0 | R21: 2 | S21: 1 | T21: =SUM(D21:K21) -> 0
A22: 15 | B22: =VLOOKUP(A22,'Data '!A15:J50,3,0) -> 0 | C22: =VLOOKUP(A22,'Data '!A15:J50,2,0) -> 0 | N22: =SUM(D22:M22) -> 0 | R22: 1 | S22: 1 | T22: =SUM(D22:K22) -> 0
A23: 16 | B23: =VLOOKUP(A23,'Data '!A16:J51,3,0) -> 0 | C23: =VLOOKUP(A23,'Data '!A16:J51,2,0) -> 0 | N23: =SUM(D23:M23) -> 0 | R23: 0.9 | S23: 0.8 | T23: =SUM(D23:K23) -> 0
A24: 17 | B24: =VLOOKUP(A24,'Data '!A17:J52,3,0) -> 0 | C24: =VLOOKUP(A24,'Data '!A17:J52,2,0) -> 0 | N24: =SUM(D24:M24) -> 0 | R24: 1 | S24: 1 | T24: =SUM(D24:K24) -> 0
A25: 18 | B25: =VLOOKUP(A25,'Data '!A18:J53,3,0) -> 0 | C25: =VLOOKUP(A25,'Data '!A18:J53,2,0) -> 0 | N25: =SUM(D25:M25) -> 0 | R25: 0.8 | S25: 0.8 | T25: =SUM(D25:K25) -> 0
A26: 19 | B26: =VLOOKUP(A26,'Data '!A19:J54,3,0) -> 0 | C26: =VLOOKUP(A26,'Data '!A19:J54,2,0) -> 0 | N26: =SUM(D26:M26) -> 0 | R26: 0.8 | S26: 0.7 | T26: =SUM(D26:K26) -> 0
... A28: 21 | B28: =VLOOKUP(A28,'Data '!A21:J56,3,0) -> 0 | C28: =VLOOKUP(A28,'Data '!A21:J56,2,0) -> 0 | N28: =SUM(D28:M28) -> 0 | R28: 0.6 | S28: 0.8 | T28: =SUM(D28:K28) -> 0
K30: ='Data '!H38 -> Tambak Jaya, September 2025
K31: Penguji
K34: ……………………………………………..

Sheet Tartil dan Fashohah
A1: D+A1:M31AFTAR NILAI UJIAN AKHIR
A2: LAJNAH MUROQOBAH YANBU'A LAMPUNG BARAT
L3: : Tartil dan Fashohah
A5: No | B5: Nama | C5: Asal RTQ | D5: Aspek Penilaian Catatan Kesalahan | L5: Total Nilai | M5: Keterangan
D7: Tajwid (1,25) | E7: Kalimat | F7: Churuf | G7: Shifat | H7: Charokat | I7: Ibtida' | J7: Tanfis | K7: Kelancaran
A8: 1 | B8: =VLOOKUP(A8,'Data '!A2:J36,3,0) -> Ahmad Alhabib Ramadhan | C8: =VLOOKUP(A8,'Data '!A2:J36,2,0) -> Utsmaniyyah III | L8: =SUM(D8:K8) -> 0 | P8: =SUM(D8:K8) -> 0
